Workbook

Sheet PARAMETROS
A1: MODELO-BASE DE FLUXO DE CAIXA SEMANAL | CONTAINER FAST & GOOD
A3: Configuração | B3: Valor | F3: Categorias de despesas | G3: Categorias de receitas | H3: Status | I3: Formas de pagamento | J3: Tipos de despesa
A4: Data inicial da projeção | B4: 46146 | F4: Aluguel | G4: iFood | H4: Previsto | I4: Conta corrente | J4: Fixa
A5: Saldo inicial em conta | B5: -6183.36 | F5: Folha / Salários | G5: Loja física | H5: Pago | I5: Pix | J5: Variável
A6: Critério de semana | B6: Segunda a domingo | F6: Encargos / FGTS | G6: Pix | H6: Recebido | I6: Boleto | J6: Imposto
A7: Quantidade de semanas projetadas | B7: 12 | F7: Impostos | G7: Cartão / Maquininha | H7: Em aberto | I7: Cartão de crédito | J7: Folha
A8: Data de atualização do controle | B8: 46158 | F8: Fornecedores | G8: Dinheiro | H8: Vencido | I8: Dinheiro | J8: Fornecedor
F9: Cartão de crédito | G9: Empréstimo | H9: Cancelado | I9: Débito automático | J9: Empréstimo
A10: Nome do cartão | B10: Dia de vencimento da fatura | C10: Banco | D10: Observação | F10: Empréstimos | G10: Aporte | I10: Transferência | J10: Aluguel
A11: Nubank | B11: 28 | C11: Nubank | D11: Ajustar vencimento se necessário | F11: Transporte | G11: Outros | I11: Outros | J11: Outros
A12: Bradesco | B12: 15 | C12: Bradesco | D12: Ajustar vencimento se necessário | F12: Alimentação / Insumos
A13: Porto | B13: 21 | C13: Porto | D13: Ajustar vencimento se necessário | F13: Marketing
F14: Sistema / Tecnologia
F15: Taxas bancárias
F16: Outros

Sheet DESPESAS
A1: ID | B1: Data de vencimento | C1: Semana início | D1: Semana fim | E1: Mês referência | F1: Categoria | G1: Descrição | H1: Fornecedor | I1: Tipo de despesa | J1: Valor previsto | K1: Valor pago | L1: Diferença | M1: Status | N1: Forma de pagamento | O1: Conta ou cartão | P1: Observações
A2: 1 | B2: 46143 | C2: =IF(B2="","",B2-WEEKDAY(B2,2)+1) -> 46139 | D2: =IF(B2="","",C2+6) -> 46145 | E2: =IF(B2="","",DATE(YEAR(B2),MONTH(B2),1)) -> 46143 | F2: Sistema / Tecnologia | G2: Previdência funcionários | H2: Bradesco | I2: Fixa | J2: 221.38 | K2: 221.38 | L2: =IF(J2="","",J2-K2) -> 0 | M2: Pago | N2: Débito automático | O2: Conta corrente
A3: 2 | B3: 46149 | C3: =IF(B3="","",B3-WEEKDAY(B3,2)+1) -> 46146 | D3: =IF(B3="","",C3+6) -> 46152 | E3: =IF(B3="","",DATE(YEAR(B3),MONTH(B3),1)) -> 46143 | F3: Folha / Salários | G3: Salário equipe | H3: Equipe | I3: Folha | J3: 6269 | K3: 6621.51 | L3: =IF(J3="","",J3-K3) -> -352.51 | M3: Pago | N3: Pix | O3: Conta corrente
A4: 3 | B4: 46149 | C4: =IF(B4="","",B4-WEEKDAY(B4,2)+1) -> 46146 | D4: =IF(B4="","",C4+6) -> 46152 | E4: =IF(B4="","",DATE(YEAR(B4),MONTH(B4),1)) -> 46143 | F4: Folha / Salários | G4: Salário sócio | H4: Sócio | I4: Folha | J4: 7500 | K4: 7700 | L4: =IF(J4="","",J4-K4) -> -200 | M4: Pago | N4: Pix | O4: Conta corrente
A5: 4 | B5: 46150 | C5: =IF(B5="","",B5-WEEKDAY(B5,2)+1) -> 46146 | D5: =IF(B5="","",C5+6) -> 46152 | E5: =IF(B5="","",DATE(YEAR(B5),MONTH(B5),1)) -> 46143 | F5: Sistema / Tecnologia | G5: Mensalidade | H5: Despacon | I5: Fornecedor | J5: 856.69 | K5: 856.69 | L5: =IF(J5="","",J5-K5) -> 0 | M5: Pago | N5: Boleto | O5: Conta corrente
A6: 5 | B6: 46150 | C6: =IF(B6="","",B6-WEEKDAY(B6,2)+1) -> 46146 | D6: =IF(B6="","",C6+6) -> 46152 | E6: =IF(B6="","",DATE(YEAR(B6),MONTH(B6),1)) -> 46143 | F6: Empréstimos | G6: Capital de Giro | H6: Bradesco | I6: Empréstimo | J6: 1777.67 | K6: 1777.67 | L6: =IF(J6="","",J6-K6) -> 0 | M6: Pago | N6: Débito automático | O6: Conta corrente
A7: 6 | B7: 46153 | C7: =IF(B7="","",B7-WEEKDAY(B7,2)+1) -> 46153 | D7: =IF(B7="","",C7+6) -> 46159 | E7: =IF(B7="","",DATE(YEAR(B7),MONTH(B7),1)) -> 46143 | F7: Fornecedores | G7: Mensalidade | H7: Control P Sistemas | I7: Fixa | J7: 232.13 | K7: 232.13 | L7: =IF(J7="","",J7-K7) -> 0 | M7: Pago | N7: Boleto | O7: Conta corrente
A8: 7 | B8: 46157 | C8: =IF(B8="","",B8-WEEKDAY(B8,2)+1) -> 46153 | D8: =IF(B8="","",C8+6) -> 46159 | E8: =IF(B8="","",DATE(YEAR(B8),MONTH(B8),1)) -> 46143 | F8: Fornecedores | G8: Telefone / internet | H8: Vivo | I8: Fixa | J8: 120 | K8: 120 | L8: =IF(J8="","",J8-K8) -> 0 | M8: Pago | N8: Débito automático | O8: Conta corrente
A9: 8 | B9: 46157 | C9: =IF(B9="","",B9-WEEKDAY(B9,2)+1) -> 46153 | D9: =IF(B9="","",C9+6) -> 46159 | E9: =IF(B9="","",DATE(YEAR(B9),MONTH(B9),1)) -> 46143 | F9: Fornecedores | G9: Tarifa conta corrente | H9: Bradesco | I9: Fornecedor | J9: 168.5 | K9: 168.5 | L9: =IF(J9="","",J9-K9) -> 0 | M9: Pago | N9: Débito automático | O9: Conta corrente
A10: 9 | B10: 46160 | C10: =IF(B10="","",B10-WEEKDAY(B10,2)+1) -> 46160 | D10: =IF(B10="","",C10+6) -> 46166 | E10: =IF(B10="","",DATE(YEAR(B10),MONTH(B10),1)) -> 46143 | F10: Folha / Salários | G10: Adiantamento equipe | H10: Equipe | I10: Folha | J10: 4000 | K10: 3355.9 | L10: =IF(J10="","",J10-K10) -> 644.1 | M10: Pago | N10: Pix | O10: Conta corrente
A11: 10 | B11: 46162 | C11: =IF(B11="","",B11-WEEKDAY(B11,2)+1) -> 46160 | D11: =IF(B11="","",C11+6) -> 46166 | E11: =IF(B11="","",DATE(YEAR(B11),MONTH(B11),1)) -> 46143 | F11: Fornecedores | G11: Medicina do trabalho | H11: Samtra | I11: Fixa | J11: 130 | K11: 130 | L11: =IF(J11="","",J11-K11) -> 0 | M11: Pago | N11: Pix | O11: Conta corrente
A12: 11 | B12: 46162 | C12: =IF(B12="","",B12-WEEKDAY(B12,2)+1) -> 46160 | D12: =IF(B12="","",C12+6) -> 46166 | E12: =IF(B12="","",DATE(YEAR(B12),MONTH(B12),1)) -> 46143 | F12: Encargos / FGTS | G12: FGTS | H12: Governo | I12: Imposto | J12: 1354.03 | K12: 1354.03 | L12: =IF(J12="","",J12-K12) -> 0 | M12: Pago | N12: Pix | O12: Conta corrente
A13: 12 | B13: 46162 | C13: =IF(B13="","",B13-WEEKDAY(B13,2)+1) -> 46160 | D13: =IF(B13="","",C13+6) -> 46166 | E13: =IF(B13="","",DATE(YEAR(B13),MONTH(B13),1)) -> 46143 | F13: Encargos / FGTS | G13: INSS | H13: Governo | I13: Imposto | J13: 1387.11 | K13: 1387.11 | L13: =IF(J13="","",J13-K13) -> 0 | M13: Pago | N13: Pix | O13: Conta corrente
... A56: 55 | B56: 46192 | C56: =IF(B56="","",B56-WEEKDAY(B56,2)+1) -> 46188 | D56: =IF(B56="","",C56+6) -> 46194 | E56: =IF(B56="","",DATE(YEAR(B56),MONTH(B56),1)) -> 46174 | F56: Folha / Salários | G56: Rescisão Francisca | H56: Equipe | I56: Folha | J56: 6713.45 | K56: 6713.45 | L56: =IF(J56="","",J56-K56) -> 0 | M56: Pago | N56: Pix | O56: Conta corrente
B57: 46195 | C57: =IF(B57="","",B57-WEEKDAY(B57,2)+1) -> 46195 | D57: =IF(B57="","",C57+6) -> 46201 | E57: =IF(B57="","",DATE(YEAR(B57),MONTH(B57),1)) -> 46174 | F57: Folha / Salários | G57: Freela Priscila | H57: Equipe | I57: Folha | J57: 700 | K57: 700 | L57: =IF(J57="","",J57-K57) -> 0 | M57: Pago | N57: Pix | O57: Conta corrente
B58: 46195 | C58: =IF(B58="","",B58-WEEKDAY(B58,2)+1) -> 46195 | D58: =IF(B58="","",C58+6) -> 46201 | E58: =IF(B58="","",DATE(YEAR(B58),MONTH(B58),1)) -> 46174 | F58: Cartão de crédito | G58: Taxa maquininha | H58: Itaú | I58: Fornecedor | J58: 83.5 | K58: 83.5 | L58: =IF(J58="","",J58-K58) -> 0 | M58: Pago | N58: Pix | O58: Conta corrente
A59: 56 | B59: 46204 | C59: =IF(B59="","",B59-WEEKDAY(B59,2)+1) -> 46202 | D59: =IF(B59="","",C59+6) -> 46208 | E59: =IF(B59="","",DATE(YEAR(B59),MONTH(B59),1)) -> 46204 | F59: Sistema / Tecnologia | G59: Previdência funcionários | H59: Bradesco | I59: Fixa | J59: 221.38 | K59: 221.38 | L59: =IF(J59="","",J59-K59) -> 0 | M59: Pago | N59: Débito automático | O59: Conta corrente
B60: 46205 | C60: =IF(B60="","",B60-WEEKDAY(B60,2)+1) -> 46202 | D60: =IF(B60="","",C60+6) -> 46208 | E60: =IF(B60="","",DATE(YEAR(B60),MONTH(B60),1)) -> 46204 | F60: Taxas bancárias | G60: Juros e IOF | H60: Bradesco | I60: Empréstimo | J60: 990.45 | K60: 990.45 | L60: =IF(J60="","",J60-K60) -> 0 | M60: Pago | N60: Débito automático | O60: Conta corrente
A61: 57 | B61: 46209 | C61: =IF(B61="","",B61-WEEKDAY(B61,2)+1) -> 46209 | D61: =IF(B61="","",C61+6) -> 46215 | E61: =IF(B61="","",DATE(YEAR(B61),MONTH(B61),1)) -> 46204 | F61: Folha / Salários | G61: Salário equipe | H61: Equipe | I61: Folha | J61: 6269 | K61: 0 | L61: =IF(J61="","",J61-K61) -> 6269 | M61: Previsto | N61: Pix | O61: Conta corrente
A62: 58 | B62: 46209 | C62: =IF(B62="","",B62-WEEKDAY(B62,2)+1) -> 46209 | D62: =IF(B62="","",C62+6) -> 46215 | E62: =IF(B62="","",DATE(YEAR(B62),MONTH(B62),1)) -> 46204 | F62: Folha / Salários | G62: Salário sócio | H62: Sócio | I62: Folha | J62: 7500 | K62: 0 | L62: =IF(J62="","",J62-K62) -> 7500 | M62: Previsto | N62: Pix | O62: Conta corrente
A63: 59 | B63: 46211 | C63: =IF(B63="","",B63-WEEKDAY(B63,2)+1) -> 46209 | D63: =IF(B63="","",C63+6) -> 46215 | E63: =IF(B63="","",DATE(YEAR(B63),MONTH(B63),1)) -> 46204 | F63: Sistema / Tecnologia | G63: Mensalidade | H63: Despacon | I63: Fornecedor | J63: 856.69 | K63: 0 | L63: =IF(J63="","",J63-K63) -> 856.69 | M63: Previsto | N63: Boleto | O63: Conta corrente
A64: 60 | B64: 46211 | C64: =IF(B64="","",B64-WEEKDAY(B64,2)+1) -> 46209 | D64: =IF(B64="","",C64+6) -> 46215 | E64: =IF(B64="","",DATE(YEAR(B64),MONTH(B64),1)) -> 46204 | F64: Empréstimos | G64: Capital de Giro | H64: Bradesco | I64: Empréstimo | J64: 1777.67 | K64: 0 | L64: =IF(J64="","",J64-K64) -> 1777.67 | M64: Previsto | N64: Débito automático | O64: Conta corrente
A65: 61 | B65: 46213 | C65: =IF(B65="","",B65-WEEKDAY(B65,2)+1) -> 46209 | D65: =IF(B65="","",C65+6) -> 46215 | E65: =IF(B65="","",DATE(YEAR(B65),MONTH(B65),1)) -> 46204 | F65: Fornecedores | G65: Mensalidade | H65: Control P Sistemas | I65: Fixa | J65: 232.13 | K65: 0 | L65: =IF(J65="","",J65-K65) -> 232.13 | M65: Previsto | N65: Boleto | O65: Conta corrente
A66: 62 | B66: 46218 | C66: =IF(B66="","",B66-WEEKDAY(B66,2)+1) -> 46216 | D66: =IF(B66="","",C66+6) -> 46222 | E66: =IF(B66="","",DATE(YEAR(B66),MONTH(B66),1)) -> 46204 | F66: Fornecedores | G66: Telefone / internet | H66: Vivo | I66: Fixa | J66: 120 | K66: 0 | L66: =IF(J66="","",J66-K66) -> 120 | M66: Previsto | N66: Débito automático | O66: Conta corrente
A67: 63 | B67: 46218 | C67: =IF(B67="","",B67-WEEKDAY(B67,2)+1) -> 46216 | D67: =IF(B67="","",C67+6) -> 46222 | E67: =IF(B67="","",DATE(YEAR(B67),MONTH(B67),1)) -> 46204 | F67: Fornecedores | G67: Tarifa conta corrente | H67: Bradesco | I67: Fornecedor | J67: 168.5 | K67: 0 | L67: =IF(J67="","",J67-K67) -> 168.5 | M67: Previsto | N67: Débito automático | O67: Conta corrente
A68: 64 | B68: 46223 | C68: =IF(B68="","",B68-WEEKDAY(B68,2)+1) -> 46223 | D68: =IF(B68="","",C68+6) -> 46229 | E68: =IF(B68="","",DATE(YEAR(B68),MONTH(B68),1)) -> 46204 | F68: Folha / Salários | G68: Adiantamento equipe | H68: Equipe | I68: Folha | J68: 4000 | K68: 0 | L68: =IF(J68="","",J68-K68) -> 4000 | M68: Previsto | N68: Pix | O68: Conta corrente
A69: 65 | B69: 46223 | C69: =IF(B69="","",B69-WEEKDAY(B69,2)+1) -> 46223 | D69: =IF(B69="","",C69+6) -> 46229 | E69: =IF(B69="","",DATE(YEAR(B69),MONTH(B69),1)) -> 46204 | F69: Fornecedores | G69: Medicina do trabalho | H69: Samtra | I69: Fixa | J69: 130 | K69: 0 | L69: =IF(J69="","",J69-K69) -> 130 | M69: Previsto | N69: Pix | O69: Conta corrente
A70: 66 | B70: 46223 | C70: =IF(B70="","",B70-WEEKDAY(B70,2)+1) -> 46223 | D70: =IF(B70="","",C70+6) -> 46229 | E70: =IF(B70="","",DATE(YEAR(B70),MONTH(B70),1)) -> 46204 | F70: Encargos / FGTS | G70: FGTS | H70: Governo | I70: Imposto | J70: 1354.03 | K70: 0 | L70: =IF(J70="","",J70-K70) -> 1354.03 | M70: Previsto | N70: Pix | O70: Conta corrente
A71: 67 | B71: 46223 | C71: =IF(B71="","",B71-WEEKDAY(B71,2)+1) -> 46223 | D71: =IF(B71="","",C71+6) -> 46229 | E71: =IF(B71="","",DATE(YEAR(B71),MONTH(B71),1)) -> 46204 | F71: Encargos / FGTS | G71: INSS | H71: Governo | I71: Imposto | J71: 1387.11 | K71: 0 | L71: =IF(J71="","",J71-K71) -> 1387.11 | M71: Previsto | N71: Pix | O71: Conta corrente
A72: 68 | B72: 46223 | C72: =IF(B72="","",B72-WEEKDAY(B72,2)+1) -> 46223 | D72: =IF(B72="","",C72+6) -> 46229 | E72: =IF(B72="","",DATE(YEAR(B72),MONTH(B72),1)) -> 46204 | F72: Impostos | G72: DAS | H72: Governo | I72: Imposto | J72: 1616.41 | K72: 0 | L72: =IF(J72="","",J72-K72) -> 1616.41 | M72: Previsto | N72: Pix | O72: Conta corrente
... A163: 159 | B163: 46351 | C163: =IF(B163="","",B163-WEEKDAY(B163,2)+1) -> 46349 | D163: =IF(B163="","",C163+6) -> 46355 | E163: =IF(B163="","",DATE(YEAR(B163),MONTH(B163),1)) -> 46327 | F163: Empréstimos | G163: Capital de Giro | H163: Ifood | I163: Empréstimo | J163: 3339.33 | K163: 0 | L163: =IF(J163="","",J163-K163) -> 3339.33 | M163: Previsto | N163: Débito automático | O163: Conta corrente
A164: 160 | C164: =IF(B164="","",B164-WEEKDAY(B164,2)+1) | D164: =IF(B164="","",C164+6) | E164: =IF(B164="","",DATE(YEAR(B164),MONTH(B164),1)) | L164: =IF(J164="","",J164-K164)
A165: 161 | C165: =IF(B165="","",B165-WEEKDAY(B165,2)+1) | D165: =IF(B165="","",C165+6) | E165: =IF(B165="","",DATE(YEAR(B165),MONTH(B165),1)) | L165: =IF(J165="","",J165-K165)
A166: 162 | C166: =IF(B166="","",B166-WEEKDAY(B166,2)+1) | D166: =IF(B166="","",C166+6) | E166: =IF(B166="","",DATE(YEAR(B166),MONTH(B166),1)) | L166: =IF(J166="","",J166-K166)
A167: 163 | C167: =IF(B167="","",B167-WEEKDAY(B167,2)+1) | D167: =IF(B167="","",C167+6) | E167: =IF(B167="","",DATE(YEAR(B167),MONTH(B167),1)) | L167: =IF(J167="","",J167-K167)
A168: 164 | C168: =IF(B168="","",B168-WEEKDAY(B168,2)+1) | D168: =IF(B168="","",C168+6) | E168: =IF(B168="","",DATE(YEAR(B168),MONTH(B168),1)) | L168: =IF(J168="","",J168-K168)
A169: 165 | C169: =IF(B169="","",B169-WEEKDAY(B169,2)+1) | D169: =IF(B169="","",C169+6) | E169: =IF(B169="","",DATE(YEAR(B169),MONTH(B169),1)) | L169: =IF(J169="","",J169-K169)
A170: 166 | C170: =IF(B170="","",B170-WEEKDAY(B170,2)+1) | D170: =IF(B170="","",C170+6) | E170: =IF(B170="","",DATE(YEAR(B170),MONTH(B170),1)) | L170: =IF(J170="","",J170-K170)
A171: 167 | C171: =IF(B171="","",B171-WEEKDAY(B171,2)+1) | D171: =IF(B171="","",C171+6) | E171: =IF(B171="","",DATE(YEAR(B171),MONTH(B171),1)) | L171: =IF(J171="","",J171-K171)
A172: 168 | C172: =IF(B172="","",B172-WEEKDAY(B172,2)+1) | D172: =IF(B172="","",C172+6) | E172: =IF(B172="","",DATE(YEAR(B172),MONTH(B172),1)) | L172: =IF(J172="","",J172-K172)
...

Sheet RECEITAS
A1: ID | B1: Data prevista de recebimento | C1: Semana início | D1: Semana fim | E1: Mês referência | F1: Canal de entrada | G1: Descrição | H1: Valor previsto | I1: Valor recebido | J1: Diferença | K1: Status | L1: Conta de destino | M1: Observações
A2: 1 | B2: 46148 | C2: =IF(B2="","",B2-WEEKDAY(B2,2)+1) -> 46146 | D2: =IF(B2="","",C2+6) -> 46152 | E2: =IF(B2="","",DATE(YEAR(B2),MONTH(B2),1)) -> 46143 | F2: iFood | G2: Repasse iFood | H2: 5000 | I2: 6.37 | J2: =IF(H2="","",I2-H2) -> -4993.63 | K2: Recebido | L2: Conta corrente
A3: 2 | B3: 46155 | C3: =IF(B3="","",B3-WEEKDAY(B3,2)+1) -> 46153 | D3: =IF(B3="","",C3+6) -> 46159 | E3: =IF(B3="","",DATE(YEAR(B3),MONTH(B3),1)) -> 46143 | F3: iFood | G3: Repasse iFood | H3: 5000 | I3: 3690.17 | J3: =IF(H3="","",I3-H3) -> -1309.83 | K3: Recebido | L3: Conta corrente
A4: 3 | B4: 46162 | C4: =IF(B4="","",B4-WEEKDAY(B4,2)+1) -> 46160 | D4: =IF(B4="","",C4+6) -> 46166 | E4: =IF(B4="","",DATE(YEAR(B4),MONTH(B4),1)) -> 46143 | F4: iFood | G4: Repasse iFood | H4: 4800 | I4: 3880.34 | J4: =IF(H4="","",I4-H4) -> -919.66 | K4: Recebido | L4: Conta corrente
A5: 4 | B5: 46169 | C5: =IF(B5="","",B5-WEEKDAY(B5,2)+1) -> 46167 | D5: =IF(B5="","",C5+6) -> 46173 | E5: =IF(B5="","",DATE(YEAR(B5),MONTH(B5),1)) -> 46143 | F5: iFood | G5: Repasse iFood | H5: 4800 | I5: 4119.69 | J5: =IF(H5="","",I5-H5) -> -680.31 | K5: Recebido | L5: Conta corrente
A6: 5 | B6: 46150 | C6: =IF(B6="","",B6-WEEKDAY(B6,2)+1) -> 46146 | D6: =IF(B6="","",C6+6) -> 46152 | E6: =IF(B6="","",DATE(YEAR(B6),MONTH(B6),1)) -> 46143 | F6: Cartão / Maquininha | G6: Entrada salão via meios de pagamento | H6: 10000 | I6: 11397.03 | J6: =IF(H6="","",I6-H6) -> 1397.03 | K6: Recebido | L6: Conta corrente
A7: 6 | B7: 46157 | C7: =IF(B7="","",B7-WEEKDAY(B7,2)+1) -> 46153 | D7: =IF(B7="","",C7+6) -> 46159 | E7: =IF(B7="","",DATE(YEAR(B7),MONTH(B7),1)) -> 46143 | F7: Cartão / Maquininha | G7: Entrada salão via meios de pagamento | H7: 10000 | I7: 8685.51 | J7: =IF(H7="","",I7-H7) -> -1314.49 | K7: Recebido | L7: Conta corrente
A8: 7 | B8: 46164 | C8: =IF(B8="","",B8-WEEKDAY(B8,2)+1) -> 46160 | D8: =IF(B8="","",C8+6) -> 46166 | E8: =IF(B8="","",DATE(YEAR(B8),MONTH(B8),1)) -> 46143 | F8: Cartão / Maquininha | G8: Entrada salão via meios de pagamento | H8: 10000 | I8: 8520.05 | J8: =IF(H8="","",I8-H8) -> -1479.95 | K8: Recebido | L8: Conta corrente
A9: 8 | B9: 46171 | C9: =IF(B9="","",B9-WEEKDAY(B9,2)+1) -> 46167 | D9: =IF(B9="","",C9+6) -> 46173 | E9: =IF(B9="","",DATE(YEAR(B9),MONTH(B9),1)) -> 46143 | F9: Cartão / Maquininha | G9: Entrada salão via meios de pagamento | H9: 10000 | I9: 8624.19 | J9: =IF(H9="","",I9-H9) -> -1375.81 | K9: Recebido | L9: Conta corrente
A10: 9 | B10: 46176 | C10: =IF(B10="","",B10-WEEKDAY(B10,2)+1) -> 46174 | D10: =IF(B10="","",C10+6) -> 46180 | E10: =IF(B10="","",DATE(YEAR(B10),MONTH(B10),1)) -> 46174 | F10: iFood | G10: Repasse iFood | H10: 4000 | I10: 3327.96 | J10: =IF(H10="","",I10-H10) -> -672.04 | K10: Recebido | L10: Conta corrente
A11: 10 | B11: 46183 | C11: =IF(B11="","",B11-WEEKDAY(B11,2)+1) -> 46181 | D11: =IF(B11="","",C11+6) -> 46187 | E11: =IF(B11="","",DATE(YEAR(B11),MONTH(B11),1)) -> 46174 | F11: iFood | G11: Repasse iFood | H11: 4000 | I11: 2794.36 | J11: =IF(H11="","",I11-H11) -> -1205.64 | K11: Recebido | L11: Conta corrente
A12: 11 | B12: 46190 | C12: =IF(B12="","",B12-WEEKDAY(B12,2)+1) -> 46188 | D12: =IF(B12="","",C12+6) -> 46194 | E12: =IF(B12="","",DATE(YEAR(B12),MONTH(B12),1)) -> 46174 | F12: iFood | G12: Repasse iFood | H12: 4000 | I12: 4148.07 | J12: =IF(H12="","",I12-H12) -> 148.07 | K12: Recebido | L12: Conta corrente
A13: 12 | B13: 46197 | C13: =IF(B13="","",B13-WEEKDAY(B13,2)+1) -> 46195 | D13: =IF(B13="","",C13+6) -> 46201 | E13: =IF(B13="","",DATE(YEAR(B13),MONTH(B13),1)) -> 46174 | F13: iFood | G13: Repasse iFood | H13: 4000 | I13: 3460.39 | J13: =IF(H13="","",I13-H13) -> -539.61 | K13: Recebido | L13: Conta corrente
... A61: 60 | B61: 46353 | C61: =IF(B61="","",B61-WEEKDAY(B61,2)+1) -> 46349 | D61: =IF(B61="","",C61+6) -> 46355 | E61: =IF(B61="","",DATE(YEAR(B61),MONTH(B61),1)) -> 46327 | F61: Cartão / Maquininha | G61: Entrada salão via meios de pagamento | H61: 10000 | I61: 0 | J61: =IF(H61="","",I61-H61) -> -10000 | K61: Previsto | L61: Conta corrente
C62: =IF(B62="","",B62-WEEKDAY(B62,2)+1) | D62: =IF(B62="","",C62+6) | E62: =IF(B62="","",DATE(YEAR(B62),MONTH(B62),1)) | J62: =IF(H62="","",I62-H62)
C63: =IF(B63="","",B63-WEEKDAY(B63,2)+1) | D63: =IF(B63="","",C63+6) | E63: =IF(B63="","",DATE(YEAR(B63),MONTH(B63),1)) | J63: =IF(H63="","",I63-H63)
C64: =IF(B64="","",B64-WEEKDAY(B64,2)+1) | D64: =IF(B64="","",C64+6) | E64: =IF(B64="","",DATE(YEAR(B64),MONTH(B64),1)) | J64: =IF(H64="","",I64-H64)
C65: =IF(B65="","",B65-WEEKDAY(B65,2)+1) | D65: =IF(B65="","",C65+6) | E65: =IF(B65="","",DATE(YEAR(B65),MONTH(B65),1)) | J65: =IF(H65="","",I65-H65)
C66: =IF(B66="","",B66-WEEKDAY(B66,2)+1) | D66: =IF(B66="","",C66+6) | E66: =IF(B66="","",DATE(YEAR(B66),MONTH(B66),1)) | J66: =IF(H66="","",I66-H66)
C67: =IF(B67="","",B67-WEEKDAY(B67,2)+1) | D67: =IF(B67="","",C67+6) | E67: =IF(B67="","",DATE(YEAR(B67),MONTH(B67),1)) | J67: =IF(H67="","",I67-H67)
C68: =IF(B68="","",B68-WEEKDAY(B68,2)+1) | D68: =IF(B68="","",C68+6) | E68: =IF(B68="","",DATE(YEAR(B68),MONTH(B68),1)) | J68: =IF(H68="","",I68-H68)
C69: =IF(B69="","",B69-WEEKDAY(B69,2)+1) | D69: =IF(B69="","",C69+6) | E69: =IF(B69="","",DATE(YEAR(B69),MONTH(B69),1)) | J69: =IF(H69="","",I69-H69)
C70: =IF(B70="","",B70-WEEKDAY(B70,2)+1) | D70: =IF(B70="","",C70+6) | E70: =IF(B70="","",DATE(YEAR(B70),MONTH(B70),1)) | J70: =IF(H70="","",I70-H70)
C71: =IF(B71="","",B71-WEEKDAY(B71,2)+1) | D71: =IF(B71="","",C71+6) | E71: =IF(B71="","",DATE(YEAR(B71),MONTH(B71),1)) | J71: =IF(H71="","",I71-H71)
C72: =IF(B72="","",B72-WEEKDAY(B72,2)+1) | D72: =IF(B72="","",C72+6) | E72: =IF(B72="","",DATE(YEAR(B72),MONTH(B72),1)) | J72: =IF(H72="","",I72-H72)
C73: =IF(B73="","",B73-WEEKDAY(B73,2)+1) | D73: =IF(B73="","",C73+6) | E73: =IF(B73="","",DATE(YEAR(B73),MONTH(B73),1)) | J73: =IF(H73="","",I73-H73)
... C200: =IF(B200="","",B200-WEEKDAY(B200,2)+1) | D200: =IF(B200="","",C200+6) | E200: =IF(B200="","",DATE(YEAR(B200),MONTH(B200),1)) | J200: =IF(H200="","",I200-H200)

Sheet CARTAO_COMPRAS
A1: ID da compra | B1: Data da compra | C1: Cartão | D1: Descrição | E1: Categoria | F1: Valor total da compra | G1: Quantidade total de parcelas | H1: Parcela atual | I1: Valor da parcela | J1: Data da primeira fatura | K1: Status | L1: Observações
A2: 1 | B2: 46028 | C2: Bradesco | D2: Swfit - Açougue | E2: Alimentação / Insumos | F2: 856.92 | G2: 4 | H2: 4 | I2: =IF(F2="","",F2/G2) -> 214.23 | J2: 46157 | K2: Pago
A3: 2 | B3: 46031 | C3: Bradesco | D3: Swfit - Açougue | E3: Alimentação / Insumos | F3: 361.68 | G3: 4 | H3: 4 | I3: =IF(F3="","",F3/G3) -> 90.42 | J3: 46157 | K3: Pago
A4: 3 | B4: 46034 | C4: Bradesco | D4: Swfit - Açougue | E4: Alimentação / Insumos | F4: 591.8 | G4: 4 | H4: 4 | I4: =IF(F4="","",F4/G4) -> 147.95 | J4: 46157 | K4: Pago
A5: 4 | B5: 46037 | C5: Bradesco | D5: Swfit - Açougue | E5: Alimentação / Insumos | F5: 256.68 | G5: 4 | H5: 4 | I5: =IF(F5="","",F5/G5) -> 64.17 | J5: 46157 | K5: Pago
A6: 5 | B6: 46041 | C6: Bradesco | D6: Swfit - Açougue | E6: Alimentação / Insumos | F6: 670.52 | G6: 4 | H6: 4 | I6: =IF(F6="","",F6/G6) -> 167.63 | J6: 46157 | K6: Pago
A7: 6 | B7: 46044 | C7: Bradesco | D7: Swfit - Açougue | E7: Alimentação / Insumos | F7: 693.32 | G7: 4 | H7: 4 | I7: =IF(F7="","",F7/G7) -> 173.33 | J7: 46157 | K7: Pago
A8: 7 | B8: 46048 | C8: Bradesco | D8: Swfit - Açougue | E8: Alimentação / Insumos | F8: 768.16 | G8: 4 | H8: 4 | I8: =IF(F8="","",F8/G8) -> 192.04 | J8: 46157 | K8: Pago
A9: 8 | B9: 46051 | C9: Bradesco | D9: Swfit - Açougue | E9: Alimentação / Insumos | F9: 256.68 | G9: 4 | H9: 4 | I9: =IF(F9="","",F9/G9) -> 64.17 | J9: 46157 | K9: Pago
A10: 9 | B10: 46055 | C10: Bradesco | D10: Swfit - Açougue | E10: Alimentação / Insumos | F10: 594.72 | G10: 4 | H10: 3 | I10: =IF(F10="","",F10/G10) -> 148.68 | J10: 46157 | K10: Pago
A11: 10 | B11: 46059 | C11: Bradesco | D11: Suplementos | E11: Alimentação / Insumos | F11: 1588 | G11: 4 | H11: 3 | I11: =IF(F11="","",F11/G11) -> 397 | J11: 46157 | K11: Pago
A12: 11 | B12: 46059 | C12: Bradesco | D12: Avental e Cia | E12: Fornecedores | F12: 1249.98 | G12: 3 | H12: 3 | I12: =IF(F12="","",F12/G12) -> 416.66 | J12: 46157 | K12: Pago
A13: 12 | B13: 46060 | C13: Bradesco | D13: Fritur fretado balada | E13: Transporte | F13: 303.66 | G13: 3 | H13: 3 | I13: =IF(F13="","",F13/G13) -> 101.22 | J13: 46157 | K13: Pago
... A25: 24 | B25: 46092 | C25: Bradesco | D25: Swfit - Açougue | E25: Alimentação / Insumos | F25: 340.08 | G25: 4 | H25: 2 | I25: =IF(F25="","",F25/G25) -> 85.02 | J25: 46157 | K25: Pago
A26: 25 | B26: 46097 | C26: Bradesco | D26: Certificado digital | F26: 232 | G26: 2 | H26: 2 | I26: =IF(F26="","",F26/G26) -> 116 | J26: 46157 | K26: Pago
A27: 26 | B27: 46097 | C27: Bradesco | D27: Westwing | E27: Alimentação / Insumos | F27: 330.45 | G27: 3 | H27: 2 | I27: =IF(F27="","",F27/G27) -> 110.15 | J27: 46157 | K27: Pago
A28: 27 | B28: 46098 | C28: Bradesco | D28: Suplementos | E28: Alimentação / Insumos | F28: 622.98 | G28: 3 | H28: 2 | I28: =IF(F28="","",F28/G28) -> 207.66 | J28: 46157 | K28: Pago
A29: 28 | B29: 46100 | C29: Bradesco | D29: Swfit - Açougue | E29: Alimentação / Insumos | F29: 959.56 | G29: 4 | H29: 2 | I29: =IF(F29="","",F29/G29) -> 239.89 | J29: 46157 | K29: Pago
A30: 29 | B30: 46102 | C30: Bradesco | D30: Sonda Supermercados | E30: Alimentação / Insumos | F30: 630.34 | G30: 2 | H30: 2 | I30: =IF(F30="","",F30/G30) -> 315.17 | J30: 46157 | K30: Pago
A31: 30 | B31: 46110 | C31: Bradesco | D31: Swfit - Açougue | E31: Alimentação / Insumos | F31: 741.56 | G31: 4 | H31: 2 | I31: =IF(F31="","",F31/G31) -> 185.39 | J31: 46157 | K31: Pago
A32: 31 | B32: 46111 | C32: Bradesco | D32: Sonda Supermercados | E32: Alimentação / Insumos | F32: 866.02 | G32: 2 | H32: 2 | I32: =IF(F32="","",F32/G32) -> 433.01 | J32: 46157 | K32: Pago
A33: 32 | B33: 46112 | C33: Bradesco | D33: Trimais - supermercado | E33: Alimentação / Insumos | F33: 348.86 | G33: 2 | H33: 2 | I33: =IF(F33="","",F33/G33) -> 174.43 | J33: 46157 | K33: Pago
A34: 33 | B34: 46114 | C34: Bradesco | D34: Giga Atacado | E34: Alimentação / Insumos | F34: 881.09 | G34: 1 | H34: 1 | I34: =IF(F34="","",F34/G34) -> 881.09 | J34: 46157 | K34: Pago
A35: 34 | B35: 46115 | C35: Bradesco | D35: Sonda Supermercados | E35: Alimentação / Insumos | F35: 297.28 | G35: 2 | H35: 1 | I35: =IF(F35="","",F35/G35) -> 148.64 | J35: 46157 | K35: Pago
A36: 35 | B36: 46116 | C36: Bradesco | D36: Sonda Supermercados | E36: Alimentação / Insumos | F36: 266.88 | G36: 2 | H36: 1 | I36: =IF(F36="","",F36/G36) -> 133.44 | J36: 46157 | K36: Pago
A37: 36 | B37: 46118 | C37: Bradesco | D37: Swfit - Açougue | E37: Alimentação / Insumos | F37: 1033.28 | G37: 4 | H37: 1 | I37: =IF(F37="","",F37/G37) -> 258.32 | J37: 46157 | K37: Pago
A38: 37 | B38: 46118 | C38: Bradesco | D38: Giga Atacado | E38: Alimentação / Insumos | F38: 1310.59 | G38: 1 | H38: 1 | I38: =IF(F38="","",F38/G38) -> 1310.59 | J38: 46157 | K38: Pago
... A139: 138 | B139: 46206 | C139: Bradesco | D139: Giga Atacado | E139: Alimentação / Insumos | F139: 600.21 | G139: 1 | H139: 1 | I139: =IF(F139="","",F139/G139) -> 600.21 | J139: 46251 | K139: Previsto
A140: 139 | C140: Bradesco | E140: Alimentação / Insumos | H140: 1 | I140: =IF(F140="","",F140/G140) | J140: 46251 | K140: Previsto
A141: 140 | C141: Bradesco | E141: Alimentação / Insumos | H141: 1 | I141: =IF(F141="","",F141/G141) | J141: 46251 | K141: Previsto
A142: 141 | C142: Bradesco | E142: Alimentação / Insumos | H142: 1 | I142: =IF(F142="","",F142/G142) | J142: 46251 | K142: Previsto
A143: 142 | C143: Bradesco | E143: Alimentação / Insumos | H143: 1 | I143: =IF(F143="","",F143/G143) | J143: 46251 | K143: Previsto
A144: 143 | C144: Bradesco | E144: Alimentação / Insumos | H144: 1 | I144: =IF(F144="","",F144/G144) | J144: 46251 | K144: Previsto
A145: 144 | C145: Bradesco | E145: Alimentação / Insumos | H145: 1 | I145: =IF(F145="","",F145/G145) | J145: 46251 | K145: Previsto
A146: 145 | C146: Bradesco | E146: Alimentação / Insumos | H146: 1 | I146: =IF(F146="","",F146/G146) | J146: 46251 | K146: Previsto
A147: 146 | C147: Bradesco | E147: Alimentação / Insumos | H147: 1 | I147: =IF(F147="","",F147/G147) | J147: 46251 | K147: Previsto
A148: 147 | C148: Bradesco | E148: Alimentação / Insumos | H148: 1 | I148: =IF(F148="","",F148/G148) | J148: 46251 | K148: Previsto
A149: 148 | C149: Bradesco | E149: Alimentação / Insumos | H149: 1 | I149: =IF(F149="","",F149/G149) | J149: 46251 | K149: Previsto
A150: 149 | C150: Bradesco | E150: Alimentação / Insumos | H150: 1 | I150: =IF(F150="","",F150/G150) | J150: 46251 | K150: Previsto
A151: 150 | C151: Bradesco | E151: Alimentação / Insumos | H151: 1 | I151: =IF(F151="","",F151/G151) | J151: 46251 | K151: Previsto
...

Sheet CARTAO_PROJECAO
A1: ID da compra | B1: Cartão | C1: Descrição | D1: Categoria | E1: Parcela | F1: Total de parcelas | G1: Valor da parcela | H1: Data de vencimento da fatura | I1: Semana início | J1: Semana fim | K1: Mês referência | L1: Status | M1: Origem
A2: =IF(OR(INDEX(CARTAO_COMPRAS!$A:$A,INT((ROW()-2)/20)+2)="",INDEX(CARTAO_COMPRAS!$G:$G,INT((ROW()-2)/20)+2)="",INDEX(CARTAO_COMPRAS!$H:$H,INT((ROW()-2)/20)+2)="",MOD(ROW()-2,20)>INDEX(CARTAO_COMPRAS!$G:$G,INT((ROW()-2)/20)+2)-INDEX(CARTAO_COMPRAS!$H:$H,INT((ROW()-2)/20)+2)),"",INDEX(CARTAO_COMPRAS!$A:$A,INT((ROW()-2)/20)+2)) -> 1 | B2: =IF($A2="","",INDEX(CARTAO_COMPRAS!$C:$C,INT((ROW()-2)/20)+2)) -> Bradesco | C2: =IF($A2="","",INDEX(CARTAO_COMPRAS!$D:$D,INT((ROW()-2)/20)+2)) -> Swfit - Açougue | D2: =IF($A2="","",INDEX(CARTAO_COMPRAS!$E:$E,INT((ROW()-2)/20)+2)) -> Alimentação / Insumos | E2: =IF($A2="","",INDEX(CARTAO_COMPRAS!$H:$H,INT((ROW()-2)/20)+2)+MOD(ROW()-2,20)) -> 4 | F2: =IF($A2="","",INDEX(CARTAO_COMPRAS!$G:$G,INT((ROW()-2)/20)+2)) -> 4 | G2: =IF($A2="","",INDEX(CARTAO_COMPRAS!$I:$I,INT((ROW()-2)/20)+2)) -> 214.23 | H2: =IF($A2="","",EDATE(INDEX(CARTAO_COMPRAS!$J:$J,INT((ROW()-2)/20)+2),MOD(ROW()-2,20))) -> 46157 | I2: =IF($H2="","",$H2-WEEKDAY($H2,2)+1) -> 46153 | J2: =IF($I2="","",$I2+6) -> 46159 | K2: =IF($H2="","",DATE(YEAR($H2),MONTH($H2),1)) -> 46143 | L2: =IF($A2="","",INDEX(CARTAO_COMPRAS!$K:$K,INT((ROW()-2)/20)+2)) -> Pago | M2: =IF($A2="","","Compra no cartão") -> Compra no cartão
A3: =IF(OR(INDEX(CARTAO_COMPRAS!$A:$A,INT((ROW()-2)/20)+2)="",INDEX(CARTAO_COMPRAS!$G:$G,INT((ROW()-2)/20)+2)="",INDEX(CARTAO_COMPRAS!$H:$H,INT((ROW()-2)/20)+2)="",MOD(ROW()-2,20)>INDEX(CARTAO_COMPRAS!$G:$G,INT((ROW()-2)/20)+2)-INDEX(CARTAO_COMPRAS!$H:$H,INT((ROW()-2)/20)+2)),"",INDEX(CARTAO_COMPRAS!$A:$A,INT((ROW()-2)/20)+2)) | B3: =IF($A3="","",INDEX(CARTAO_COMPRAS!$C:$C,INT((ROW()-2)/20)+2)) | C3: =IF($A3="","",INDEX(CARTAO_COMPRAS!$D:$D,INT((ROW()-2)/20)+2)) | D3: =IF($A3="","",INDEX(CARTAO_COMPRAS!$E:$E,INT((ROW()-2)/20)+2)) | E3: =IF($A3="","",INDEX(CARTAO_COMPRAS!$H:$H,INT((ROW()-2)/20)+2)+MOD(ROW()-2,20)) | F3: =IF($A3="","",INDEX(CARTAO_COMPRAS!$G:$G,INT((ROW()-2)/20)+2)) | G3: =IF($A3="","",INDEX(CARTAO_COMPRAS!$I:$I,INT((ROW()-2)/20)+2)) | H3: =IF($A3="","",EDATE(INDEX(CARTAO_COMPRAS!$J:$J,INT((ROW()-2)/20)+2),MOD(ROW()-2,20))) | I3: =IF($H3="","",$H3-WEEKDAY($H3,2)+1) | J3: =IF($I3="","",$I3+6) | K3: =IF($H3="","",DATE(YEAR($H3),MONTH($H3),1)) | L3: =IF($A3="","",INDEX(CARTAO_COMPRAS!$K:$K,INT((ROW()-2)/20)+2)) | M3: =IF($A3="","","Compra no cartão")
A4: =IF(OR(INDEX(CARTAO_COMPRAS!$A:$A,INT((ROW()-2)/20)+2)="",INDEX(CARTAO_COMPRAS!$G:$G,INT((ROW()-2)/20)+2)="",INDEX(CARTAO_COMPRAS!$H:$H,INT((ROW()-2)/20)+2)="",MOD(ROW()-2,20)>INDEX(CARTAO_COMPRAS!$G:$G,INT((ROW()-2)/20)+2)-INDEX(CARTAO_COMPRAS!$H:$H,INT((ROW()-2)/20)+2)),"",INDEX(CARTAO_COMPRAS!$A:$A,INT((ROW()-2)/20)+2)) | B4: =IF($A4="","",INDEX(CARTAO_COMPRAS!$C:$C,INT((ROW()-2)/20)+2)) | C4: =IF($A4="","",INDEX(CARTAO_COMPRAS!$D:$D,INT((ROW()-2)/20)+2)) | D4: =IF($A4="","",INDEX(CARTAO_COMPRAS!$E:$E,INT((ROW()-2)/20)+2)) | E4: =IF($A4="","",INDEX(CARTAO_COMPRAS!$H:$H,INT((ROW()-2)/20)+2)+MOD(ROW()-2,20)) | F4: =IF($A4="","",INDEX(CARTAO_COMPRAS!$G:$G,INT((ROW()-2)/20)+2)) | G4: =IF($A4="","",INDEX(CARTAO_COMPRAS!$I:$I,INT((ROW()-2)/20)+2)) | H4: =IF($A4="","",EDATE(INDEX(CARTAO_COMPRAS!$J:$J,INT((ROW()-2)/20)+2),MOD(ROW()-2,20))) | I4: =IF($H4="","",$H4-WEEKDAY($H4,2)+1) | J4: =IF($I4="","",$I4+6) | K4: =IF($H4="","",DATE(YEAR($H4),MONTH($H4),1)) | L4: =IF($A4="","",INDEX(CARTAO_COMPRAS!$K:$K,INT((ROW()-2)/20)+2)) | M4: =IF($A4="","","Compra no cartão")
A5: =IF(OR(INDEX(CARTAO_COMPRAS!$A:$A,INT((ROW()-2)/20)+2)="",INDEX(CARTAO_COMPRAS!$G:$G,INT((ROW()-2)/20)+2)="",INDEX(CARTAO_COMPRAS!$H:$H,INT((ROW()-2)/20)+2)="",MOD(ROW()-2,20)>INDEX(CARTAO_COMPRAS!$G:$G,INT((ROW()-2)/20)+2)-INDEX(CARTAO_COMPRAS!$H:$H,INT((ROW()-2)/20)+2)),"",INDEX(CARTAO_COMPRAS!$A:$A,INT((ROW()-2)/20)+2)) | B5: =IF($A5="","",INDEX(CARTAO_COMPRAS!$C:$C,INT((ROW()-2)/20)+2)) | C5: =IF($A5="","",INDEX(CARTAO_COMPRAS!$D:$D,INT((ROW()-2)/20)+2)) | D5: =IF($A5="","",INDEX(CARTAO_COMPRAS!$E:$E,INT((ROW()-2)/20)+2)) | E5: =IF($A5="","",INDEX(CARTAO_COMPRAS!$H:$H,INT((ROW()-2)/20)+2)+MOD(ROW()-2,20)) | F5: =IF($A5="","",INDEX(CARTAO_COMPRAS!$G:$G,INT((ROW()-2)/20)+2)) | G5: =IF($A5="","",INDEX(CARTAO_COMPRAS!$I:$I,INT((ROW()-2)/20)+2)) | H5: =IF($A5="","",EDATE(INDEX(CARTAO_COMPRAS!$J:$J,INT((ROW()-2)/20)+2),MOD(ROW()-2,20))) | I5: =IF($H5="","",$H5-WEEKDAY($H5,2)+1) | J5: =IF($I5="","",$I5+6) | K5: =IF($H5="","",DATE(YEAR($H5),MONTH($H5),1)) | L5: =IF($A5="","",INDEX(CARTAO_COMPRAS!$K:$K,INT((ROW()-2)/20)+2)) | M5: =IF($A5="","","Compra no cartão")
A6: =IF(OR(INDEX(CARTAO_COMPRAS!$A:$A,INT((ROW()-2)/20)+2)="",INDEX(CARTAO_COMPRAS!$G:$G,INT((ROW()-2)/20)+2)="",INDEX(CARTAO_COMPRAS!$H:$H,INT((ROW()-2)/20)+2)="",MOD(ROW()-2,20)>INDEX(CARTAO_COMPRAS!$G:$G,INT((ROW()-2)/20)+2)-INDEX(CARTAO_COMPRAS!$H:$H,INT((ROW()-2)/20)+2)),"",INDEX(CARTAO_COMPRAS!$A:$A,INT((ROW()-2)/20)+2)) | B6: =IF($A6="","",INDEX(CARTAO_COMPRAS!$C:$C,INT((ROW()-2)/20)+2)) | C6: =IF($A6="","",INDEX(CARTAO_COMPRAS!$D:$D,INT((ROW()-2)/20)+2)) | D6: =IF($A6="","",INDEX(CARTAO_COMPRAS!$E:$E,INT((ROW()-2)/20)+2)) | E6: =IF($A6="","",INDEX(CARTAO_COMPRAS!$H:$H,INT((ROW()-2)/20)+2)+MOD(ROW()-2,20)) | F6: =IF($A6="","",INDEX(CARTAO_COMPRAS!$G:$G,INT((ROW()-2)/20)+2)) | G6: =IF($A6="","",INDEX(CARTAO_COMPRAS!$I:$I,INT((ROW()-2)/20)+2)) | H6: =IF($A6="","",EDATE(INDEX(CARTAO_COMPRAS!$J:$J,INT((ROW()-2)/20)+2),MOD(ROW()-2,20))) | I6: =IF($H6="","",$H6-WEEKDAY($H6,2)+1) | J6: =IF($I6="","",$I6+6) | K6: =IF($H6="","",DATE(YEAR($H6),MONTH($H6),1)) | L6: =IF($A6="","",INDEX(CARTAO_COMPRAS!$K:$K,INT((ROW()-2)/20)+2)) | M6: =IF($A6="","","Compra no cartão")
A7: =IF(OR(INDEX(CARTAO_COMPRAS!$A:$A,INT((ROW()-2)/20)+2)="",INDEX(CARTAO_COMPRAS!$G:$G,INT((ROW()-2)/20)+2)="",INDEX(CARTAO_COMPRAS!$H:$H,INT((ROW()-2)/20)+2)="",MOD(ROW()-2,20)>INDEX(CARTAO_COMPRAS!$G:$G,INT((ROW()-2)/20)+2)-INDEX(CARTAO_COMPRAS!$H:$H,INT((ROW()-2)/20)+2)),"",INDEX(CARTAO_COMPRAS!$A:$A,INT((ROW()-2)/20)+2)) | B7: =IF($A7="","",INDEX(CARTAO_COMPRAS!$C:$C,INT((ROW()-2)/20)+2)) | C7: =IF($A7="","",INDEX(CARTAO_COMPRAS!$D:$D,INT((ROW()-2)/20)+2)) | D7: =IF($A7="","",INDEX(CARTAO_COMPRAS!$E:$E,INT((ROW()-2)/20)+2)) | E7: =IF($A7="","",INDEX(CARTAO_COMPRAS!$H:$H,INT((ROW()-2)/20)+2)+MOD(ROW()-2,20)) | F7: =IF($A7="","",INDEX(CARTAO_COMPRAS!$G:$G,INT((ROW()-2)/20)+2)) | G7: =IF($A7="","",INDEX(CARTAO_COMPRAS!$I:$I,INT((ROW()-2)/20)+2)) | H7: =IF($A7="","",EDATE(INDEX(CARTAO_COMPRAS!$J:$J,INT((ROW()-2)/20)+2),MOD(ROW()-2,20))) | I7: =IF($H7="","",$H7-WEEKDAY($H7,2)+1) | J7: =IF($I7="","",$I7+6) | K7: =IF($H7="","",DATE(YEAR($H7),MONTH($H7),1)) | L7: =IF($A7="","",INDEX(CARTAO_COMPRAS!$K:$K,INT((ROW()-2)/20)+2)) | M7: =IF($A7="","","Compra no cartão")
A8: =IF(OR(INDEX(CARTAO_COMPRAS!$A:$A,INT((ROW()-2)/20)+2)="",INDEX(CARTAO_COMPRAS!$G:$G,INT((ROW()-2)/20)+2)="",INDEX(CARTAO_COMPRAS!$H:$H,INT((ROW()-2)/20)+2)="",MOD(ROW()-2,20)>INDEX(CARTAO_COMPRAS!$G:$G,INT((ROW()-2)/20)+2)-INDEX(CARTAO_COMPRAS!$H:$H,INT((ROW()-2)/20)+2)),"",INDEX(CARTAO_COMPRAS!$A:$A,INT((ROW()-2)/20)+2)) | B8: =IF($A8="","",INDEX(CARTAO_COMPRAS!$C:$C,INT((ROW()-2)/20)+2)) | C8: =IF($A8="","",INDEX(CARTAO_COMPRAS!$D:$D,INT((ROW()-2)/20)+2)) | D8: =IF($A8="","",INDEX(CARTAO_COMPRAS!$E:$E,INT((ROW()-2)/20)+2)) | E8: =IF($A8="","",INDEX(CARTAO_COMPRAS!$H:$H,INT((ROW()-2)/20)+2)+MOD(ROW()-2,20)) | F8: =IF($A8="","",INDEX(CARTAO_COMPRAS!$G:$G,INT((ROW()-2)/20)+2)) | G8: =IF($A8="","",INDEX(CARTAO_COMPRAS!$I:$I,INT((ROW()-2)/20)+2)) | H8: =IF($A8="","",EDATE(INDEX(CARTAO_COMPRAS!$J:$J,INT((ROW()-2)/20)+2),MOD(ROW()-2,20))) | I8: =IF($H8="","",$H8-WEEKDAY($H8,2)+1) | J8: =IF($I8="","",$I8+6) | K8: =IF($H8="","",DATE(YEAR($H8),MONTH($H8),1)) | L8: =IF($A8="","",INDEX(CARTAO_COMPRAS!$K:$K,INT((ROW()-2)/20)+2)) | M8: =IF($A8="","","Compra no cartão")
A9: =IF(OR(INDEX(CARTAO_COMPRAS!$A:$A,INT((ROW()-2)/20)+2)="",INDEX(CARTAO_COMPRAS!$G:$G,INT((ROW()-2)/20)+2)="",INDEX(CARTAO_COMPRAS!$H:$H,INT((ROW()-2)/20)+2)="",MOD(ROW()-2,20)>INDEX(CARTAO_COMPRAS!$G:$G,INT((ROW()-2)/20)+2)-INDEX(CARTAO_COMPRAS!$H:$H,INT((ROW()-2)/20)+2)),"",INDEX(CARTAO_COMPRAS!$A:$A,INT((ROW()-2)/20)+2)) | B9: =IF($A9="","",INDEX(CARTAO_COMPRAS!$C:$C,INT((ROW()-2)/20)+2)) | C9: =IF($A9="","",INDEX(CARTAO_COMPRAS!$D:$D,INT((ROW()-2)/20)+2)) | D9: =IF($A9="","",INDEX(CARTAO_COMPRAS!$E:$E,INT((ROW()-2)/20)+2)) | E9: =IF($A9="","",INDEX(CARTAO_COMPRAS!$H:$H,INT((ROW()-2)/20)+2)+MOD(ROW()-2,20)) | F9: =IF($A9="","",INDEX(CARTAO_COMPRAS!$G:$G,INT((ROW()-2)/20)+2)) | G9: =IF($A9="","",INDEX(CARTAO_COMPRAS!$I:$I,INT((ROW()-2)/20)+2)) | H9: =IF($A9="","",EDATE(INDEX(CARTAO_COMPRAS!$J:$J,INT((ROW()-2)/20)+2),MOD(ROW()-2,20))) | I9: =IF($H9="","",$H9-WEEKDAY($H9,2)+1) | J9: =IF($I9="","",$I9+6) | K9: =IF($H9="","",DATE(YEAR($H9),MONTH($H9),1)) | L9: =IF($A9="","",INDEX(CARTAO_COMPRAS!$K:$K,INT((ROW()-2)/20)+2)) | M9: =IF($A9="","","Compra no cartão")
A10: =IF(OR(INDEX(CARTAO_COMPRAS!$A:$A,INT((ROW()-2)/20)+2)="",INDEX(CARTAO_COMPRAS!$G:$G,INT((ROW()-2)/20)+2)="",INDEX(CARTAO_COMPRAS!$H:$H,INT((ROW()-2)/20)+2)="",MOD(ROW()-2,20)>INDEX(CARTAO_COMPRAS!$G:$G,INT((ROW()-2)/20)+2)-INDEX(CARTAO_COMPRAS!$H:$H,INT((ROW()-2)/20)+2)),"",INDEX(CARTAO_COMPRAS!$A:$A,INT((ROW()-2)/20)+2)) | B10: =IF($A10="","",INDEX(CARTAO_COMPRAS!$C:$C,INT((ROW()-2)/20)+2)) | C10: =IF($A10="","",INDEX(CARTAO_COMPRAS!$D:$D,INT((ROW()-2)/20)+2)) | D10: =IF($A10="","",INDEX(CARTAO_COMPRAS!$E:$E,INT((ROW()-2)/20)+2)) | E10: =IF($A10="","",INDEX(CARTAO_COMPRAS!$H:$H,INT((ROW()-2)/20)+2)+MOD(ROW()-2,20)) | F10: =IF($A10="","",INDEX(CARTAO_COMPRAS!$G:$G,INT((ROW()-2)/20)+2)) | G10: =IF($A10="","",INDEX(CARTAO_COMPRAS!$I:$I,INT((ROW()-2)/20)+2)) | H10: =IF($A10="","",EDATE(INDEX(CARTAO_COMPRAS!$J:$J,INT((ROW()-2)/20)+2),MOD(ROW()-2,20))) | I10: =IF($H10="","",$H10-WEEKDAY($H10,2)+1) | J10: =IF($I10="","",$I10+6) | K10: =IF($H10="","",DATE(YEAR($H10),MONTH($H10),1)) | L10: =IF($A10="","",INDEX(CARTAO_COMPRAS!$K:$K,INT((ROW()-2)/20)+2)) | M10: =IF($A10="","","Compra no cartão")
A11: =IF(OR(INDEX(CARTAO_COMPRAS!$A:$A,INT((ROW()-2)/20)+2)="",INDEX(CARTAO_COMPRAS!$G:$G,INT((ROW()-2)/20)+2)="",INDEX(CARTAO_COMPRAS!$H:$H,INT((ROW()-2)/20)+2)="",MOD(ROW()-2,20)>INDEX(CARTAO_COMPRAS!$G:$G,INT((ROW()-2)/20)+2)-INDEX(CARTAO_COMPRAS!$H:$H,INT((ROW()-2)/20)+2)),"",INDEX(CARTAO_COMPRAS!$A:$A,INT((ROW()-2)/20)+2)) | B11: =IF($A11="","",INDEX(CARTAO_COMPRAS!$C:$C,INT((ROW()-2)/20)+2)) | C11: =IF($A11="","",INDEX(CARTAO_COMPRAS!$D:$D,INT((ROW()-2)/20)+2)) | D11: =IF($A11="","",INDEX(CARTAO_COMPRAS!$E:$E,INT((ROW()-2)/20)+2)) | E11: =IF($A11="","",INDEX(CARTAO_COMPRAS!$H:$H,INT((ROW()-2)/20)+2)+MOD(ROW()-2,20)) | F11: =IF($A11="","",INDEX(CARTAO_COMPRAS!$G:$G,INT((ROW()-2)/20)+2)) | G11: =IF($A11="","",INDEX(CARTAO_COMPRAS!$I:$I,INT((ROW()-2)/20)+2)) | H11: =IF($A11="","",EDATE(INDEX(CARTAO_COMPRAS!$J:$J,INT((ROW()-2)/20)+2),MOD(ROW()-2,20))) | I11: =IF($H11="","",$H11-WEEKDAY($H11,2)+1) | J11: =IF($I11="","",$I11+6) | K11: =IF($H11="","",DATE(YEAR($H11),MONTH($H11),1)) | L11: =IF($A11="","",INDEX(CARTAO_COMPRAS!$K:$K,INT((ROW()-2)/20)+2)) | M11: =IF($A11="","","Compra no cartão")
A12: =IF(OR(INDEX(CARTAO_COMPRAS!$A:$A,INT((ROW()-2)/20)+2)="",INDEX(CARTAO_COMPRAS!$G:$G,INT((ROW()-2)/20)+2)="",INDEX(CARTAO_COMPRAS!$H:$H,INT((ROW()-2)/20)+2)="",MOD(ROW()-2,20)>INDEX(CARTAO_COMPRAS!$G:$G,INT((ROW()-2)/20)+2)-INDEX(CARTAO_COMPRAS!$H:$H,INT((ROW()-2)/20)+2)),"",INDEX(CARTAO_COMPRAS!$A:$A,INT((ROW()-2)/20)+2)) | B12: =IF($A12="","",INDEX(CARTAO_COMPRAS!$C:$C,INT((ROW()-2)/20)+2)) | C12: =IF($A12="","",INDEX(CARTAO_COMPRAS!$D:$D,INT((ROW()-2)/20)+2)) | D12: =IF($A12="","",INDEX(CARTAO_COMPRAS!$E:$E,INT((ROW()-2)/20)+2)) | E12: =IF($A12="","",INDEX(CARTAO_COMPRAS!$H:$H,INT((ROW()-2)/20)+2)+MOD(ROW()-2,20)) | F12: =IF($A12="","",INDEX(CARTAO_COMPRAS!$G:$G,INT((ROW()-2)/20)+2)) | G12: =IF($A12="","",INDEX(CARTAO_COMPRAS!$I:$I,INT((ROW()-2)/20)+2)) | H12: =IF($A12="","",EDATE(INDEX(CARTAO_COMPRAS!$J:$J,INT((ROW()-2)/20)+2),MOD(ROW()-2,20))) | I12: =IF($H12="","",$H12-WEEKDAY($H12,2)+1) | J12: =IF($I12="","",$I12+6) | K12: =IF($H12="","",DATE(YEAR($H12),MONTH($H12),1)) | L12: =IF($A12="","",INDEX(CARTAO_COMPRAS!$K:$K,INT((ROW()-2)/20)+2)) | M12: =IF($A12="","","Compra no cartão")
A13: =IF(OR(INDEX(CARTAO_COMPRAS!$A:$A,INT((ROW()-2)/20)+2)="",INDEX(CARTAO_COMPRAS!$G:$G,INT((ROW()-2)/20)+2)="",INDEX(CARTAO_COMPRAS!$H:$H,INT((ROW()-2)/20)+2)="",MOD(ROW()-2,20)>INDEX(CARTAO_COMPRAS!$G:$G,INT((ROW()-2)/20)+2)-INDEX(CARTAO_COMPRAS!$H:$H,INT((ROW()-2)/20)+2)),"",INDEX(CARTAO_COMPRAS!$A:$A,INT((ROW()-2)/20)+2)) | B13: =IF($A13="","",INDEX(CARTAO_COMPRAS!$C:$C,INT((ROW()-2)/20)+2)) | C13: =IF($A13="","",INDEX(CARTAO_COMPRAS!$D:$D,INT((ROW()-2)/20)+2)) | D13: =IF($A13="","",INDEX(CARTAO_COMPRAS!$E:$E,INT((ROW()-2)/20)+2)) | E13: =IF($A13="","",INDEX(CARTAO_COMPRAS!$H:$H,INT((ROW()-2)/20)+2)+MOD(ROW()-2,20)) | F13: =IF($A13="","",INDEX(CARTAO_COMPRAS!$G:$G,INT((ROW()-2)/20)+2)) | G13: =IF($A13="","",INDEX(CARTAO_COMPRAS!$I:$I,INT((ROW()-2)/20)+2)) | H13: =IF($A13="","",EDATE(INDEX(CARTAO_COMPRAS!$J:$J,INT((ROW()-2)/20)+2),MOD(ROW()-2,20))) | I13: =IF($H13="","",$H13-WEEKDAY($H13,2)+1) | J13: =IF($I13="","",$I13+6) | K13: =IF($H13="","",DATE(YEAR($H13),MONTH($H13),1)) | L13: =IF($A13="","",INDEX(CARTAO_COMPRAS!$K:$K,INT((ROW()-2)/20)+2)) | M13: =IF($A13="","","Compra no cartão")
... A12083: =IF(OR(INDEX(CARTAO_COMPRAS!$A:$A,INT((ROW()-2)/20)+2)="",INDEX(CARTAO_COMPRAS!$G:$G,INT((ROW()-2)/20)+2)="",INDEX(CARTAO_COMPRAS!$H:$H,INT((ROW()-2)/20)+2)="",MOD(ROW()-2,20)>INDEX(CARTAO_COMPRAS!$G:$G,INT((ROW()-2)/20)+2)-INDEX(CARTAO_COMPRAS!$H:$H,INT((ROW()-2)/20)+2)),"",INDEX(CARTAO_COMPRAS!$A:$A,INT((ROW()-2)/20)+2)) | B12083: =IF($A12083="","",INDEX(CARTAO_COMPRAS!$C:$C,INT((ROW()-2)/20)+2)) | C12083: =IF($A12083="","",INDEX(CARTAO_COMPRAS!$D:$D,INT((ROW()-2)/20)+2)) | D12083: =IF($A12083="","",INDEX(CARTAO_COMPRAS!$E:$E,INT((ROW()-2)/20)+2)) | E12083: =IF($A12083="","",INDEX(CARTAO_COMPRAS!$H:$H,INT((ROW()-2)/20)+2)+MOD(ROW()-2,20)) | F12083: =IF($A12083="","",INDEX(CARTAO_COMPRAS!$G:$G,INT((ROW()-2)/20)+2)) | G12083: =IF($A12083="","",INDEX(CARTAO_COMPRAS!$I:$I,INT((ROW()-2)/20)+2)) | H12083: =IF($A12083="","",EDATE(INDEX(CARTAO_COMPRAS!$J:$J,INT((ROW()-2)/20)+2),MOD(ROW()-2,20))) | I12083: =IF($H12083="","",$H12083-WEEKDAY($H12083,2)+1) | J12083: =IF($I12083="","",$I12083+6) | K12083: =IF($H12083="","",DATE(YEAR($H12083),MONTH($H12083),1)) | L12083: =IF($A12083="","",INDEX(CARTAO_COMPRAS!$K:$K,INT((ROW()-2)/20)+2)) | M12083: =IF($A12083="","","Compra no cartão")

Sheet FLUXO_SEMANAL
A1: Semana | B1: Data início da semana | C1: Data fim da semana | D1: Saldo inicial | E1: Entradas previstas | F1: Entradas realizadas | G1: Total de entradas considerado | H1: Despesas previstas | I1: Despesas pagas | J1: Cartões previstos | K1: Total de saídas considerado | L1: Saldo projetado | M1: Saldo realizado | N1: Necessidade de caixa | O1: Alerta | P1: Observações
A2: =ROW()-1 -> 1 | B2: =PARAMETROS!$B$4-WEEKDAY(PARAMETROS!$B$4,2)+1 -> 46146 | C2: =B2+6 -> 46152 | D2: =PARAMETROS!$B$5 -> -6183.36 | E2: =SUMIFS(RECEITAS!$H:$H,RECEITAS!$C:$C,$B2) -> 15000 | F2: =SUMIFS(RECEITAS!$I:$I,RECEITAS!$C:$C,$B2,RECEITAS!$K:$K,"Recebido") -> 11403.4 | G2: =SUMIFS(RECEITAS!$I:$I,RECEITAS!$C:$C,$B2,RECEITAS!$K:$K,"Recebido")+SUMIFS(RECEITAS!$H:$H,RECEITAS!$C:$C,$B2,RECEITAS!$K:$K,"<>Recebido") -> 11403.4 | H2: =SUMIFS(DESPESAS!$J:$J,DESPESAS!$C:$C,$B2) -> 17221.26 | I2: =SUMIFS(DESPESAS!$K:$K,DESPESAS!$C:$C,$B2,DESPESAS!$M:$M,"Pago") -> 17773.77 | J2: =SUMIFS(CARTAO_PROJECAO!$G:$G,CARTAO_PROJECAO!$H:$H,">="&$B2,CARTAO_PROJECAO!$H:$H,"<="&$C2) -> 0 | K2: =SUMIFS(DESPESAS!$K:$K,DESPESAS!$C:$C,$B2,DESPESAS!$M:$M,"Pago")+SUMIFS(DESPESAS!$J:$J,DESPESAS!$C:$C,$B2,DESPESAS!$M:$M,"<>Pago")+$J2 -> 17773.77 | L2: =D2+G2-K2 -> -12553.73 | M2: =D2+F2-I2-J2 -> -12553.73 | N2: =IF(L2<0,ABS(L2),0) -> 12553.73 | O2: =IF(L2<0,"CRÍTICO",IF(L2<1000,"ATENÇÃO","OK")) -> CRÍTICO
A3: =ROW()-1 -> 2 | B3: =B2+7 -> 46153 | C3: =B3+6 -> 46159 | D3: =L2 -> -12553.73 | E3: =SUMIFS(RECEITAS!$H:$H,RECEITAS!$C:$C,$B3) -> 15000 | F3: =SUMIFS(RECEITAS!$I:$I,RECEITAS!$C:$C,$B3,RECEITAS!$K:$K,"Recebido") -> 12375.68 | G3: =SUMIFS(RECEITAS!$I:$I,RECEITAS!$C:$C,$B3,RECEITAS!$K:$K,"Recebido")+SUMIFS(RECEITAS!$H:$H,RECEITAS!$C:$C,$B3,RECEITAS!$K:$K,"<>Recebido") -> 12375.68 | H3: =SUMIFS(DESPESAS!$J:$J,DESPESAS!$C:$C,$B3) -> 520.63 | I3: =SUMIFS(DESPESAS!$K:$K,DESPESAS!$C:$C,$B3,DESPESAS!$M:$M,"Pago") -> 520.63 | J3: =SUMIFS(CARTAO_PROJECAO!$G:$G,CARTAO_PROJECAO!$H:$H,">="&$B3,CARTAO_PROJECAO!$H:$H,"<="&$C3) -> 21614.8 | K3: =SUMIFS(DESPESAS!$K:$K,DESPESAS!$C:$C,$B3,DESPESAS!$M:$M,"Pago")+SUMIFS(DESPESAS!$J:$J,DESPESAS!$C:$C,$B3,DESPESAS!$M:$M,"<>Pago")+$J3 -> 22135.43 | L3: =D3+G3-K3 -> -22313.48 | M3: =D3+F3-I3-J3 -> -22313.48 | N3: =IF(L3<0,ABS(L3),0) -> 22313.48 | O3: =IF(L3<0,"CRÍTICO",IF(L3<1000,"ATENÇÃO","OK")) -> CRÍTICO
A4: =ROW()-1 -> 3 | B4: =B3+7 -> 46160 | C4: =B4+6 -> 46166 | D4: =L3 -> -22313.48 | E4: =SUMIFS(RECEITAS!$H:$H,RECEITAS!$C:$C,$B4) -> 14800 | F4: =SUMIFS(RECEITAS!$I:$I,RECEITAS!$C:$C,$B4,RECEITAS!$K:$K,"Recebido") -> 12400.39 | G4: =SUMIFS(RECEITAS!$I:$I,RECEITAS!$C:$C,$B4,RECEITAS!$K:$K,"Recebido")+SUMIFS(RECEITAS!$H:$H,RECEITAS!$C:$C,$B4,RECEITAS!$K:$K,"<>Recebido") -> 12400.39 | H4: =SUMIFS(DESPESAS!$J:$J,DESPESAS!$C:$C,$B4) -> 16495.5 | I4: =SUMIFS(DESPESAS!$K:$K,DESPESAS!$C:$C,$B4,DESPESAS!$M:$M,"Pago") -> 15851.4 | J4: =SUMIFS(CARTAO_PROJECAO!$G:$G,CARTAO_PROJECAO!$H:$H,">="&$B4,CARTAO_PROJECAO!$H:$H,"<="&$C4) -> 0 | K4: =SUMIFS(DESPESAS!$K:$K,DESPESAS!$C:$C,$B4,DESPESAS!$M:$M,"Pago")+SUMIFS(DESPESAS!$J:$J,DESPESAS!$C:$C,$B4,DESPESAS!$M:$M,"<>Pago")+$J4 -> 15851.4 | L4: =D4+G4-K4 -> -25764.49 | M4: =D4+F4-I4-J4 -> -25764.49 | N4: =IF(L4<0,ABS(L4),0) -> 25764.49 | O4: =IF(L4<0,"CRÍTICO",IF(L4<1000,"ATENÇÃO","OK")) -> CRÍTICO
A5: =ROW()-1 -> 4 | B5: =B4+7 -> 46167 | C5: =B5+6 -> 46173 | D5: =L4 -> -25764.49 | E5: =SUMIFS(RECEITAS!$H:$H,RECEITAS!$C:$C,$B5) -> 14800 | F5: =SUMIFS(RECEITAS!$I:$I,RECEITAS!$C:$C,$B5,RECEITAS!$K:$K,"Recebido") -> 12743.88 | G5: =SUMIFS(RECEITAS!$I:$I,RECEITAS!$C:$C,$B5,RECEITAS!$K:$K,"Recebido")+SUMIFS(RECEITAS!$H:$H,RECEITAS!$C:$C,$B5,RECEITAS!$K:$K,"<>Recebido") -> 12743.88 | H5: =SUMIFS(DESPESAS!$J:$J,DESPESAS!$C:$C,$B5) -> 15199.35 | I5: =SUMIFS(DESPESAS!$K:$K,DESPESAS!$C:$C,$B5,DESPESAS!$M:$M,"Pago") -> 14800.95 | J5: =SUMIFS(CARTAO_PROJECAO!$G:$G,CARTAO_PROJECAO!$H:$H,">="&$B5,CARTAO_PROJECAO!$H:$H,"<="&$C5) -> 7944.79 | K5: =SUMIFS(DESPESAS!$K:$K,DESPESAS!$C:$C,$B5,DESPESAS!$M:$M,"Pago")+SUMIFS(DESPESAS!$J:$J,DESPESAS!$C:$C,$B5,DESPESAS!$M:$M,"<>Pago")+$J5 -> 22745.74 | L5: =D5+G5-K5 -> -35766.35 | M5: =D5+F5-I5-J5 -> -35766.35 | N5: =IF(L5<0,ABS(L5),0) -> 35766.35 | O5: =IF(L5<0,"CRÍTICO",IF(L5<1000,"ATENÇÃO","OK")) -> CRÍTICO
A6: =ROW()-1 -> 5 | B6: =B5+7 -> 46174 | C6: =B6+6 -> 46180 | D6: =L5 -> -35766.35 | E6: =SUMIFS(RECEITAS!$H:$H,RECEITAS!$C:$C,$B6) -> 14000 | F6: =SUMIFS(RECEITAS!$I:$I,RECEITAS!$C:$C,$B6,RECEITAS!$K:$K,"Recebido") -> 13149.94 | G6: =SUMIFS(RECEITAS!$I:$I,RECEITAS!$C:$C,$B6,RECEITAS!$K:$K,"Recebido")+SUMIFS(RECEITAS!$H:$H,RECEITAS!$C:$C,$B6,RECEITAS!$K:$K,"<>Recebido") -> 13149.94 | H6: =SUMIFS(DESPESAS!$J:$J,DESPESAS!$C:$C,$B6) -> 14140.38 | I6: =SUMIFS(DESPESAS!$K:$K,DESPESAS!$C:$C,$B6,DESPESAS!$M:$M,"Pago") -> 14385.96 | J6: =SUMIFS(CARTAO_PROJECAO!$G:$G,CARTAO_PROJECAO!$H:$H,">="&$B6,CARTAO_PROJECAO!$H:$H,"<="&$C6) -> 0 | K6: =SUMIFS(DESPESAS!$K:$K,DESPESAS!$C:$C,$B6,DESPESAS!$M:$M,"Pago")+SUMIFS(DESPESAS!$J:$J,DESPESAS!$C:$C,$B6,DESPESAS!$M:$M,"<>Pago")+$J6 -> 14385.96 | L6: =D6+G6-K6 -> -37002.37 | M6: =D6+F6-I6-J6 -> -37002.37 | N6: =IF(L6<0,ABS(L6),0) -> 37002.37 | O6: =IF(L6<0,"CRÍTICO",IF(L6<1000,"ATENÇÃO","OK")) -> CRÍTICO
A7: =ROW()-1 -> 6 | B7: =B6+7 -> 46181 | C7: =B7+6 -> 46187 | D7: =L6 -> -37002.37 | E7: =SUMIFS(RECEITAS!$H:$H,RECEITAS!$C:$C,$B7) -> 14000 | F7: =SUMIFS(RECEITAS!$I:$I,RECEITAS!$C:$C,$B7,RECEITAS!$K:$K,"Recebido") -> 11873.56 | G7: =SUMIFS(RECEITAS!$I:$I,RECEITAS!$C:$C,$B7,RECEITAS!$K:$K,"Recebido")+SUMIFS(RECEITAS!$H:$H,RECEITAS!$C:$C,$B7,RECEITAS!$K:$K,"<>Recebido") -> 11873.56 | H7: =SUMIFS(DESPESAS!$J:$J,DESPESAS!$C:$C,$B7) -> 2866.49 | I7: =SUMIFS(DESPESAS!$K:$K,DESPESAS!$C:$C,$B7,DESPESAS!$M:$M,"Pago") -> 4482.03 | J7: =SUMIFS(CARTAO_PROJECAO!$G:$G,CARTAO_PROJECAO!$H:$H,">="&$B7,CARTAO_PROJECAO!$H:$H,"<="&$C7) -> 0 | K7: =SUMIFS(DESPESAS!$K:$K,DESPESAS!$C:$C,$B7,DESPESAS!$M:$M,"Pago")+SUMIFS(DESPESAS!$J:$J,DESPESAS!$C:$C,$B7,DESPESAS!$M:$M,"<>Pago")+$J7 -> 4482.03 | L7: =D7+G7-K7 -> -29610.84 | M7: =D7+F7-I7-J7 -> -29610.84 | N7: =IF(L7<0,ABS(L7),0) -> 29610.84 | O7: =IF(L7<0,"CRÍTICO",IF(L7<1000,"ATENÇÃO","OK")) -> CRÍTICO
A8: =ROW()-1 -> 7 | B8: =B7+7 -> 46188 | C8: =B8+6 -> 46194 | D8: =L7 -> -29610.84 | E8: =SUMIFS(RECEITAS!$H:$H,RECEITAS!$C:$C,$B8) -> 14000 | F8: =SUMIFS(RECEITAS!$I:$I,RECEITAS!$C:$C,$B8,RECEITAS!$K:$K,"Recebido") -> 11497.75 | G8: =SUMIFS(RECEITAS!$I:$I,RECEITAS!$C:$C,$B8,RECEITAS!$K:$K,"Recebido")+SUMIFS(RECEITAS!$H:$H,RECEITAS!$C:$C,$B8,RECEITAS!$K:$K,"<>Recebido") -> 11497.75 | H8: =SUMIFS(DESPESAS!$J:$J,DESPESAS!$C:$C,$B8) -> 18751.33 | I8: =SUMIFS(DESPESAS!$K:$K,DESPESAS!$C:$C,$B8,DESPESAS!$M:$M,"Pago") -> 18045.23 | J8: =SUMIFS(CARTAO_PROJECAO!$G:$G,CARTAO_PROJECAO!$H:$H,">="&$B8,CARTAO_PROJECAO!$H:$H,"<="&$C8) -> 20906.985 | K8: =SUMIFS(DESPESAS!$K:$K,DESPESAS!$C:$C,$B8,DESPESAS!$M:$M,"Pago")+SUMIFS(DESPESAS!$J:$J,DESPESAS!$C:$C,$B8,DESPESAS!$M:$M,"<>Pago")+$J8 -> 38952.215 | L8: =D8+G8-K8 -> -57065.305 | M8: =D8+F8-I8-J8 -> -57065.305 | N8: =IF(L8<0,ABS(L8),0) -> 57065.305 | O8: =IF(L8<0,"CRÍTICO",IF(L8<1000,"ATENÇÃO","OK")) -> CRÍTICO
A9: =ROW()-1 -> 8 | B9: =B8+7 -> 46195 | C9: =B9+6 -> 46201 | D9: =L8 -> -57065.305 | E9: =SUMIFS(RECEITAS!$H:$H,RECEITAS!$C:$C,$B9) -> 14000 | F9: =SUMIFS(RECEITAS!$I:$I,RECEITAS!$C:$C,$B9,RECEITAS!$K:$K,"Recebido") -> 9838.39 | G9: =SUMIFS(RECEITAS!$I:$I,RECEITAS!$C:$C,$B9,RECEITAS!$K:$K,"Recebido")+SUMIFS(RECEITAS!$H:$H,RECEITAS!$C:$C,$B9,RECEITAS!$K:$K,"<>Recebido") -> 9838.39 | H9: =SUMIFS(DESPESAS!$J:$J,DESPESAS!$C:$C,$B9) -> 10405.95 | I9: =SUMIFS(DESPESAS!$K:$K,DESPESAS!$C:$C,$B9,DESPESAS!$M:$M,"Pago") -> 10438.76 | J9: =SUMIFS(CARTAO_PROJECAO!$G:$G,CARTAO_PROJECAO!$H:$H,">="&$B9,CARTAO_PROJECAO!$H:$H,"<="&$C9) -> 8626.67 | K9: =SUMIFS(DESPESAS!$K:$K,DESPESAS!$C:$C,$B9,DESPESAS!$M:$M,"Pago")+SUMIFS(DESPESAS!$J:$J,DESPESAS!$C:$C,$B9,DESPESAS!$M:$M,"<>Pago")+$J9 -> 19065.43 | L9: =D9+G9-K9 -> -66292.345 | M9: =D9+F9-I9-J9 -> -66292.345 | N9: =IF(L9<0,ABS(L9),0) -> 66292.345 | O9: =IF(L9<0,"CRÍTICO",IF(L9<1000,"ATENÇÃO","OK")) -> CRÍTICO
A10: =ROW()-1 -> 9 | B10: =B9+7 -> 46202 | C10: =B10+6 -> 46208 | D10: =L9 -> -66292.345 | E10: =SUMIFS(RECEITAS!$H:$H,RECEITAS!$C:$C,$B10) -> 15000 | F10: =SUMIFS(RECEITAS!$I:$I,RECEITAS!$C:$C,$B10,RECEITAS!$K:$K,"Recebido") -> 0 | G10: =SUMIFS(RECEITAS!$I:$I,RECEITAS!$C:$C,$B10,RECEITAS!$K:$K,"Recebido")+SUMIFS(RECEITAS!$H:$H,RECEITAS!$C:$C,$B10,RECEITAS!$K:$K,"<>Recebido") -> 15000 | H10: =SUMIFS(DESPESAS!$J:$J,DESPESAS!$C:$C,$B10) -> 9071.28 | I10: =SUMIFS(DESPESAS!$K:$K,DESPESAS!$C:$C,$B10,DESPESAS!$M:$M,"Pago") -> 6071.28 | J10: =SUMIFS(CARTAO_PROJECAO!$G:$G,CARTAO_PROJECAO!$H:$H,">="&$B10,CARTAO_PROJECAO!$H:$H,"<="&$C10) -> 0 | K10: =SUMIFS(DESPESAS!$K:$K,DESPESAS!$C:$C,$B10,DESPESAS!$M:$M,"Pago")+SUMIFS(DESPESAS!$J:$J,DESPESAS!$C:$C,$B10,DESPESAS!$M:$M,"<>Pago")+$J10 -> 9071.28 | L10: =D10+G10-K10 -> -60363.625 | M10: =D10+F10-I10-J10 -> -72363.625 | N10: =IF(L10<0,ABS(L10),0) -> 60363.625 | O10: =IF(L10<0,"CRÍTICO",IF(L10<1000,"ATENÇÃO","OK")) -> CRÍTICO
A11: =ROW()-1 -> 10 | B11: =B10+7 -> 46209 | C11: =B11+6 -> 46215 | D11: =L10 -> -60363.625 | E11: =SUMIFS(RECEITAS!$H:$H,RECEITAS!$C:$C,$B11) -> 15000 | F11: =SUMIFS(RECEITAS!$I:$I,RECEITAS!$C:$C,$B11,RECEITAS!$K:$K,"Recebido") -> 0 | G11: =SUMIFS(RECEITAS!$I:$I,RECEITAS!$C:$C,$B11,RECEITAS!$K:$K,"Recebido")+SUMIFS(RECEITAS!$H:$H,RECEITAS!$C:$C,$B11,RECEITAS!$K:$K,"<>Recebido") -> 15000 | H11: =SUMIFS(DESPESAS!$J:$J,DESPESAS!$C:$C,$B11) -> 16635.49 | I11: =SUMIFS(DESPESAS!$K:$K,DESPESAS!$C:$C,$B11,DESPESAS!$M:$M,"Pago") -> 0 | J11: =SUMIFS(CARTAO_PROJECAO!$G:$G,CARTAO_PROJECAO!$H:$H,">="&$B11,CARTAO_PROJECAO!$H:$H,"<="&$C11) -> 0 | K11: =SUMIFS(DESPESAS!$K:$K,DESPESAS!$C:$C,$B11,DESPESAS!$M:$M,"Pago")+SUMIFS(DESPESAS!$J:$J,DESPESAS!$C:$C,$B11,DESPESAS!$M:$M,"<>Pago")+$J11 -> 16635.49 | L11: =D11+G11-K11 -> -61999.115 | M11: =D11+F11-I11-J11 -> -60363.625 | N11: =IF(L11<0,ABS(L11),0) -> 61999.115 | O11: =IF(L11<0,"CRÍTICO",IF(L11<1000,"ATENÇÃO","OK")) -> CRÍTICO
A12: =ROW()-1 -> 11 | B12: =B11+7 -> 46216 | C12: =B12+6 -> 46222 | D12: =L11 -> -61999.115 | E12: =SUMIFS(RECEITAS!$H:$H,RECEITAS!$C:$C,$B12) -> 15000 | F12: =SUMIFS(RECEITAS!$I:$I,RECEITAS!$C:$C,$B12,RECEITAS!$K:$K,"Recebido") -> 0 | G12: =SUMIFS(RECEITAS!$I:$I,RECEITAS!$C:$C,$B12,RECEITAS!$K:$K,"Recebido")+SUMIFS(RECEITAS!$H:$H,RECEITAS!$C:$C,$B12,RECEITAS!$K:$K,"<>Recebido") -> 15000 | H12: =SUMIFS(DESPESAS!$J:$J,DESPESAS!$C:$C,$B12) -> 288.5 | I12: =SUMIFS(DESPESAS!$K:$K,DESPESAS!$C:$C,$B12,DESPESAS!$M:$M,"Pago") -> 0 | J12: =SUMIFS(CARTAO_PROJECAO!$G:$G,CARTAO_PROJECAO!$H:$H,">="&$B12,CARTAO_PROJECAO!$H:$H,"<="&$C12) -> 18983.452 | K12: =SUMIFS(DESPESAS!$K:$K,DESPESAS!$C:$C,$B12,DESPESAS!$M:$M,"Pago")+SUMIFS(DESPESAS!$J:$J,DESPESAS!$C:$C,$B12,DESPESAS!$M:$M,"<>Pago")+$J12 -> 19271.952 | L12: =D12+G12-K12 -> -66271.068 | M12: =D12+F12-I12-J12 -> -80982.568 | N12: =IF(L12<0,ABS(L12),0) -> 66271.068 | O12: =IF(L12<0,"CRÍTICO",IF(L12<1000,"ATENÇÃO","OK")) -> CRÍTICO
A13: =ROW()-1 -> 12 | B13: =B12+7 -> 46223 | C13: =B13+6 -> 46229 | D13: =L12 -> -66271.068 | E13: =SUMIFS(RECEITAS!$H:$H,RECEITAS!$C:$C,$B13) -> 15000 | F13: =SUMIFS(RECEITAS!$I:$I,RECEITAS!$C:$C,$B13,RECEITAS!$K:$K,"Recebido") -> 0 | G13: =SUMIFS(RECEITAS!$I:$I,RECEITAS!$C:$C,$B13,RECEITAS!$K:$K,"Recebido")+SUMIFS(RECEITAS!$H:$H,RECEITAS!$C:$C,$B13,RECEITAS!$K:$K,"<>Recebido") -> 15000 | H13: =SUMIFS(DESPESAS!$J:$J,DESPESAS!$C:$C,$B13) -> 16995.5 | I13: =SUMIFS(DESPESAS!$K:$K,DESPESAS!$C:$C,$B13,DESPESAS!$M:$M,"Pago") -> 0 | J13: =SUMIFS(CARTAO_PROJECAO!$G:$G,CARTAO_PROJECAO!$H:$H,">="&$B13,CARTAO_PROJECAO!$H:$H,"<="&$C13) -> 0 | K13: =SUMIFS(DESPESAS!$K:$K,DESPESAS!$C:$C,$B13,DESPESAS!$M:$M,"Pago")+SUMIFS(DESPESAS!$J:$J,DESPESAS!$C:$C,$B13,DESPESAS!$M:$M,"<>Pago")+$J13 -> 16995.5 | L13: =D13+G13-K13 -> -68266.568 | M13: =D13+F13-I13-J13 -> -66271.068 | N13: =IF(L13<0,ABS(L13),0) -> 68266.568 | O13: =IF(L13<0,"CRÍTICO",IF(L13<1000,"ATENÇÃO","OK")) -> CRÍTICO
A14: =ROW()-1 -> 13 | B14: =B13+7 -> 46230 | C14: =B14+6 -> 46236 | D14: =L13 -> -68266.568 | E14: =SUMIFS(RECEITAS!$H:$H,RECEITAS!$C:$C,$B14) -> 11500 | F14: =SUMIFS(RECEITAS!$I:$I,RECEITAS!$C:$C,$B14,RECEITAS!$K:$K,"Recebido") -> 0 | G14: =SUMIFS(RECEITAS!$I:$I,RECEITAS!$C:$C,$B14,RECEITAS!$K:$K,"Recebido")+SUMIFS(RECEITAS!$H:$H,RECEITAS!$C:$C,$B14,RECEITAS!$K:$K,"<>Recebido") -> 11500 | H14: =SUMIFS(DESPESAS!$J:$J,DESPESAS!$C:$C,$B14) -> 11280.83 | I14: =SUMIFS(DESPESAS!$K:$K,DESPESAS!$C:$C,$B14,DESPESAS!$M:$M,"Pago") -> 0 | J14: =SUMIFS(CARTAO_PROJECAO!$G:$G,CARTAO_PROJECAO!$H:$H,">="&$B14,CARTAO_PROJECAO!$H:$H,"<="&$C14) -> 6432.215 | K14: =SUMIFS(DESPESAS!$K:$K,DESPESAS!$C:$C,$B14,DESPESAS!$M:$M,"Pago")+SUMIFS(DESPESAS!$J:$J,DESPESAS!$C:$C,$B14,DESPESAS!$M:$M,"<>Pago")+$J14 -> 17713.045 | L14: =D14+G14-K14 -> -74479.613 | M14: =D14+F14-I14-J14 -> -74698.783 | N14: =IF(L14<0,ABS(L14),0) -> 74479.613 | O14: =IF(L14<0,"CRÍTICO",IF(L14<1000,"ATENÇÃO","OK")) -> CRÍTICO
... A53: =ROW()-1 -> 52 | B53: =B52+7 -> 46503 | C53: =B53+6 -> 46509 | D53: =L52 -> -15840.71 | E53: =SUMIFS(RECEITAS!$H:$H,RECEITAS!$C:$C,$B53) -> 0 | F53: =SUMIFS(RECEITAS!$I:$I,RECEITAS!$C:$C,$B53,RECEITAS!$K:$K,"Recebido") -> 0 | G53: =SUMIFS(RECEITAS!$I:$I,RECEITAS!$C:$C,$B53,RECEITAS!$K:$K,"Recebido")+SUMIFS(RECEITAS!$H:$H,RECEITAS!$C:$C,$B53,RECEITAS!$K:$K,"<>Recebido") -> 0 | H53: =SUMIFS(DESPESAS!$J:$J,DESPESAS!$C:$C,$B53) -> 0 | I53: =SUMIFS(DESPESAS!$K:$K,DESPESAS!$C:$C,$B53,DESPESAS!$M:$M,"Pago") -> 0 | J53: =SUMIFS(CARTAO_PROJECAO!$G:$G,CARTAO_PROJECAO!$H:$H,">="&$B53,CARTAO_PROJECAO!$H:$H,"<="&$C53) -> 0 | K53: =SUMIFS(DESPESAS!$K:$K,DESPESAS!$C:$C,$B53,DESPESAS!$M:$M,"Pago")+SUMIFS(DESPESAS!$J:$J,DESPESAS!$C:$C,$B53,DESPESAS!$M:$M,"<>Pago")+$J53 -> 0 | L53: =D53+G53-K53 -> -15840.71 | M53: =D53+F53-I53-J53 -> -15840.71 | N53: =IF(L53<0,ABS(L53),0) -> 15840.71 | O53: =IF(L53<0,"CRÍTICO",IF(L53<1000,"ATENÇÃO","OK")) -> CRÍTICO

Sheet RESUMO_MENSAL
A1: Mês | B1: Entradas previstas | C1: Entradas realizadas | D1: Despesas previstas | E1: Despesas pagas | F1: Cartões previstos | G1: Saldo projetado do mês | H1: Maior semana de risco | I1: Necessidade máxima de caixa | J1: Observações | L1: Resumo visual simples (V1)
A2: =DATE(YEAR(PARAMETROS!$B$4),MONTH(PARAMETROS!$B$4),1) -> 46143 | B2: =SUMIFS(FLUXO_SEMANAL!$E:$E,FLUXO_SEMANAL!$B:$B,">="&A2,FLUXO_SEMANAL!$B:$B,"<"&EDATE(A2,1)) -> 59600 | C2: =SUMIFS(FLUXO_SEMANAL!$F:$F,FLUXO_SEMANAL!$B:$B,">="&A2,FLUXO_SEMANAL!$B:$B,"<"&EDATE(A2,1)) -> 48923.35 | D2: =SUMIFS(FLUXO_SEMANAL!$H:$H,FLUXO_SEMANAL!$B:$B,">="&A2,FLUXO_SEMANAL!$B:$B,"<"&EDATE(A2,1)) -> 49436.74 | E2: =SUMIFS(FLUXO_SEMANAL!$I:$I,FLUXO_SEMANAL!$B:$B,">="&A2,FLUXO_SEMANAL!$B:$B,"<"&EDATE(A2,1)) -> 48946.75 | F2: =SUMIFS(FLUXO_SEMANAL!$J:$J,FLUXO_SEMANAL!$B:$B,">="&A2,FLUXO_SEMANAL!$B:$B,"<"&EDATE(A2,1)) -> 29559.59 | G2: =IFERROR(_xlfn.XLOOKUP(EOMONTH(A2,0),FLUXO_SEMANAL!$C:$C,FLUXO_SEMANAL!$L:$L,,-1),0) -> -35766.35 | H2: =IFERROR(TEXT(INDEX(FLUXO_SEMANAL!$B$2:$B$500,MATCH(_xlfn.MINIFS(FLUXO_SEMANAL!$L$2:$L$500,FLUXO_SEMANAL!$B$2:$B$500,">="&A2,FLUXO_SEMANAL!$B$2:$B$500,"<="&EOMONTH(A2,0)),FLUXO_SEMANAL!$L$2:$L$500,0)),"dd/mm")&" a "&TEXT(INDEX(FLUXO_SEMANAL!$C$2:$C$500,MATCH(_xlfn.MINIFS(FLUXO_SEMANAL!$L$2:$L$500,FLUXO_SEMANAL!$B$2:$B$500,">="&A2,FLUXO_SEMANAL!$B$2:$B$500,"<="&EOMONTH(A2,0)),FLUXO_SEMANAL!$L$2:$L$500,0)),"dd/mm"),"") -> 25/05 a 31/05 | I2: =IFERROR(_xlfn.MAXIFS(FLUXO_SEMANAL!$N:$N,FLUXO_SEMANAL!$B:$B,">="&A2,FLUXO_SEMANAL!$B:$B,"<="&EOMONTH(A2,0)),0) -> 35766.35
A3: =EDATE(A2,1) -> 46174 | B3: =SUMIFS(FLUXO_SEMANAL!$E:$E,FLUXO_SEMANAL!$B:$B,">="&A3,FLUXO_SEMANAL!$B:$B,"<"&EDATE(A3,1)) -> 71000 | C3: =SUMIFS(FLUXO_SEMANAL!$F:$F,FLUXO_SEMANAL!$B:$B,">="&A3,FLUXO_SEMANAL!$B:$B,"<"&EDATE(A3,1)) -> 46359.64 | D3: =SUMIFS(FLUXO_SEMANAL!$H:$H,FLUXO_SEMANAL!$B:$B,">="&A3,FLUXO_SEMANAL!$B:$B,"<"&EDATE(A3,1)) -> 55235.43 | E3: =SUMIFS(FLUXO_SEMANAL!$I:$I,FLUXO_SEMANAL!$B:$B,">="&A3,FLUXO_SEMANAL!$B:$B,"<"&EDATE(A3,1)) -> 53423.26 | F3: =SUMIFS(FLUXO_SEMANAL!$J:$J,FLUXO_SEMANAL!$B:$B,">="&A3,FLUXO_SEMANAL!$B:$B,"<"&EDATE(A3,1)) -> 29533.655 | G3: =IFERROR(_xlfn.XLOOKUP(EOMONTH(A3,0),FLUXO_SEMANAL!$C:$C,FLUXO_SEMANAL!$L:$L,,-1),0) -> 0 | H3: =IFERROR(TEXT(INDEX(FLUXO_SEMANAL!$B$2:$B$500,MATCH(_xlfn.MINIFS(FLUXO_SEMANAL!$L$2:$L$500,FLUXO_SEMANAL!$B$2:$B$500,">="&A3,FLUXO_SEMANAL!$B$2:$B$500,"<="&EOMONTH(A3,0)),FLUXO_SEMANAL!$L$2:$L$500,0)),"dd/mm")&" a "&TEXT(INDEX(FLUXO_SEMANAL!$C$2:$C$500,MATCH(_xlfn.MINIFS(FLUXO_SEMANAL!$L$2:$L$500,FLUXO_SEMANAL!$B$2:$B$500,">="&A3,FLUXO_SEMANAL!$B$2:$B$500,"<="&EOMONTH(A3,0)),FLUXO_SEMANAL!$L$2:$L$500,0)),"dd/mm"),"") -> 22/06 a 28/06 | I3: =IFERROR(_xlfn.MAXIFS(FLUXO_SEMANAL!$N:$N,FLUXO_SEMANAL!$B:$B,">="&A3,FLUXO_SEMANAL!$B:$B,"<="&EOMONTH(A3,0)),0) -> 66292.345
A4: =EDATE(A3,1) -> 46204 | B4: =SUMIFS(FLUXO_SEMANAL!$E:$E,FLUXO_SEMANAL!$B:$B,">="&A4,FLUXO_SEMANAL!$B:$B,"<"&EDATE(A4,1)) -> 56500 | C4: =SUMIFS(FLUXO_SEMANAL!$F:$F,FLUXO_SEMANAL!$B:$B,">="&A4,FLUXO_SEMANAL!$B:$B,"<"&EDATE(A4,1)) -> 0 | D4: =SUMIFS(FLUXO_SEMANAL!$H:$H,FLUXO_SEMANAL!$B:$B,">="&A4,FLUXO_SEMANAL!$B:$B,"<"&EDATE(A4,1)) -> 45200.32 | E4: =SUMIFS(FLUXO_SEMANAL!$I:$I,FLUXO_SEMANAL!$B:$B,">="&A4,FLUXO_SEMANAL!$B:$B,"<"&EDATE(A4,1)) -> 0 | F4: =SUMIFS(FLUXO_SEMANAL!$J:$J,FLUXO_SEMANAL!$B:$B,">="&A4,FLUXO_SEMANAL!$B:$B,"<"&EDATE(A4,1)) -> 25415.667 | G4: =IFERROR(_xlfn.XLOOKUP(EOMONTH(A4,0),FLUXO_SEMANAL!$C:$C,FLUXO_SEMANAL!$L:$L,,-1),0) -> 0 | H4: =IFERROR(TEXT(INDEX(FLUXO_SEMANAL!$B$2:$B$500,MATCH(_xlfn.MINIFS(FLUXO_SEMANAL!$L$2:$L$500,FLUXO_SEMANAL!$B$2:$B$500,">="&A4,FLUXO_SEMANAL!$B$2:$B$500,"<="&EOMONTH(A4,0)),FLUXO_SEMANAL!$L$2:$L$500,0)),"dd/mm")&" a "&TEXT(INDEX(FLUXO_SEMANAL!$C$2:$C$500,MATCH(_xlfn.MINIFS(FLUXO_SEMANAL!$L$2:$L$500,FLUXO_SEMANAL!$B$2:$B$500,">="&A4,FLUXO_SEMANAL!$B$2:$B$500,"<="&EOMONTH(A4,0)),FLUXO_SEMANAL!$L$2:$L$500,0)),"dd/mm"),"") -> 27/07 a 02/08 | I4: =IFERROR(_xlfn.MAXIFS(FLUXO_SEMANAL!$N:$N,FLUXO_SEMANAL!$B:$B,">="&A4,FLUXO_SEMANAL!$B:$B,"<="&EOMONTH(A4,0)),0) -> 74479.613
